Workbook

Sheet Typecode Reference
B1: Manufacturer | C1: Class | D1: Designation | E1: Primary Data | H1: Refractive Indices | M1: Dispersions | S1: Coefficients of Dispersion Formulae | Z1: Physical Properties | AC1: Remarks
E2: nd | F2: vd | G2: ve | H2: nC | I2: nd | J2: ne | K2: nF | L2: ng | M2: nF-nC | N2: nd-nC | O2: ng-nF | P2: θd,C | Q2: θg,F | R2: Δθg,F | S2: Formula | T2: a1 | U2: a2 | V2: a3 | W2: a4 | X2: a5 | Y2: a6 | Z2: ρ (g/cm3) | AA2: Tg (°C) | AB2: Tsoft (°C) | AC2: Precision Molding | AD2: Status | AE2: Other Comments
A3: 1 | B3: Ohara | C3: CaF | D3: S-FPL51 | E3: =I3 -> 1.4969993 | F3: =(I3-1)/M3 -> 81.546845 | G3: {=_xlfn.LET( _xlpm.λe, Addendum!$A$47/1000, _xlpm.λF, Addendum!$A$63/1000, _xlpm.λC, Addendum!$A$38/1000, _xlpm.EqName, INDEX($S:$S, ROW()), _xlpm.a_1, INDEX($T:$T, ROW()), _xlpm.a_2, INDEX($U:$U, ROW()), _xlpm.a_3, INDEX($V:$V, ROW()), _xlpm.a_4, INDEX($W:$W, ROW()), _xlpm.a_5, INDEX($X:$X, ROW()), _xlpm.a_6, INDEX($Y:$Y, ROW()), _xlpm.b_1, IF(ISNUMBER(SEARCH("Schott 3/4", _xlpm.EqName)), IFERROR(_xlfn.TEXTAFTER(INDEX($AE:$AE, ROW()), "="), 0), 0), _xlpm.Sellmeier, _xlfn.LAMBDA(_xlpm.λ, _xlpm.a_1*_xlpm.λ^2/(_xlpm.λ^2-_xlpm.a_4) + _xlpm.a_2*_xlpm.λ^2/(_xlpm.λ^2-_xlpm.a_5) + _xlpm.a_3*_xlpm.λ^2/(_xlpm.λ^2-_xlpm.a_6)), _xlpm.Schott, _xlfn.LAMBDA(_xlpm.λ, _xlpm.a_1 + _xlpm.a_2*(_xlpm.λ^2) + _xlpm.b_1*(_xlpm.λ^4) + _xlpm.a_3*(_xlpm.λ^-2) + _xlpm.a_4*(_xlpm.λ^-4) + _xlpm.a_5*(_xlpm.λ^-6) + _xlpm.a_6*(_xlpm.λ^-8)), _xlpm.RefrIndex, _xlfn.LAMBDA(_xlpm.λ, IF(ISNUMBER(SEARCH("Sellmeier", _xlpm.EqName)), IF(ISNUMBER(SEARCH("Mod", _xlpm.EqName)), SQRT((2*_xlpm.Sellmeier(_xlpm.λ)+1)/(1-_xlpm.Sellmeier(_xlpm.λ))), SQRT(1+_xlpm.Sellmeier(_xlpm.λ)) ), IF(ISNUMBER(SEARCH("Schott", _xlpm.EqName)), SQRT(_xlpm.Schott(_xlpm.λ)), NA() ) ) ), _xlpm.ne, _xlpm.RefrIndex(_xlpm.λe), _xlpm.nF, _xlpm.RefrIndex(_xlpm.λF), _xlpm.nC, _xlpm.RefrIndex(_xlpm.λC), (_xlpm.ne - 1)/(_xlpm.nF - _xlpm.nC) )} -> 81.15263 | H3: {=_xlfn.LET( _xlpm.λX, _xlfn.SWITCH(INDEX($2:$2, COLUMN()), "nC", Addendum!$A$37/1000, "nd", Addendum!$A$46/1000, "ne", Addendum!$A$47/1000, "nF", Addendum!$A$62/1000, "ng", Addendum!$A$69/1000, ), _xlpm.EqName, INDEX($S:$S, ROW()), _xlpm.a_1, INDEX($T:$T, ROW()), _xlpm.a_2, INDEX($U:$U, ROW()), _xlpm.a_3, INDEX($V:$V, ROW()), _xlpm.a_4, INDEX($W:$W, ROW()), _xlpm.a_5, INDEX($X:$X, ROW()), _xlpm.a_6, INDEX($Y:$Y, ROW()), _xlpm.b_1, IF(ISNUMBER(SEARCH("Schott 3/4", _xlpm.EqName)), IFERROR(_xlfn.TEXTAFTER(INDEX($AE:$AE, ROW()), "="), 0), 0), _xlpm.Sellmeier, _xlfn.LAMBDA(_xlpm.λ, _xlpm.a_1*_xlpm.λ^2/(_xlpm.λ^2-_xlpm.a_4) + _xlpm.a_2*_xlpm.λ^2/(_xlpm.λ^2-_xlpm.a_5) + _xlpm.a_3*_xlpm.λ^2/(_xlpm.λ^2-_xlpm.a_6)), _xlpm.Schott, _xlfn.LAMBDA(_xlpm.λ, _xlpm.a_1 + _xlpm.a_2*(_xlpm.λ^2) + _xlpm.b_1*(_xlpm.λ^4) + _xlpm.a_3*(_xlpm.λ^-2) + _xlpm.a_4*(_xlpm.λ^-4) + _xlpm.a_5*(_xlpm.λ^-6) + _xlpm.a_6*(_xlpm.λ^-8)), IF(ISNUMBER(SEARCH("Sellmeier", _xlpm.EqName)), IF(ISNUMBER(SEARCH("Mod", _xlpm.EqName)), SQRT((2*_xlpm.Sellmeier(_xlpm.λX)+1)/(1-_xlpm.Sellmeier(_xlpm.λX))), SQRT(1+_xlpm.Sellmeier(_xlpm.λX)) ), IF(ISNUMBER(SEARCH("Schott", _xlpm.EqName)), SQRT(_xlpm.Schott(_xlpm.λX)), NA() ) ) )} -> 1.4951364 | I3: {=_xlfn.LET( _xlpm.λX, _xlfn.SWITCH(INDEX($2:$2, COLUMN()), "nC", Addendum!$A$37/1000, "nd", Addendum!$A$46/1000, "ne", Addendum!$A$47/1000, "nF", Addendum!$A$62/1000, "ng", Addendum!$A$69/1000, ), _xlpm.EqName, INDEX($S:$S, ROW()), _xlpm.a_1, INDEX($T:$T, ROW()), _xlpm.a_2, INDEX($U:$U, ROW()), _xlpm.a_3, INDEX($V:$V, ROW()), _xlpm.a_4, INDEX($W:$W, ROW()), _xlpm.a_5, INDEX($X:$X, ROW()), _xlpm.a_6, INDEX($Y:$Y, ROW()), _xlpm.b_1, IF(ISNUMBER(SEARCH("Schott 3/4", _xlpm.EqName)), IFERROR(_xlfn.TEXTAFTER(INDEX($AE:$AE, ROW()), "="), 0), 0), _xlpm.Sellmeier, _xlfn.LAMBDA(_xlpm.λ, _xlpm.a_1*_xlpm.λ^2/(_xlpm.λ^2-_xlpm.a_4) + _xlpm.a_2*_xlpm.λ^2/(_xlpm.λ^2-_xlpm.a_5) + _xlpm.a_3*_xlpm.λ^2/(_xlpm.λ^2-_xlpm.a_6)), _xlpm.Schott, _xlfn.LAMBDA(_xlpm.λ, _xlpm.a_1 + _xlpm.a_2*(_xlpm.λ^2) + _xlpm.b_1*(_xlpm.λ^4) + _xlpm.a_3*(_xlpm.λ^-2) + _xlpm.a_4*(_xlpm.λ^-4) + _xlpm.a_5*(_xlpm.λ^-6) + _xlpm.a_6*(_xlpm.λ^-8)), IF(ISNUMBER(SEARCH("Sellmeier", _xlpm.EqName)), IF(ISNUMBER(SEARCH("Mod", _xlpm.EqName)), SQRT((2*_xlpm.Sellmeier(_xlpm.λX)+1)/(1-_xlpm.Sellmeier(_xlpm.λX))), SQRT(1+_xlpm.Sellmeier(_xlpm.λX)) ), IF(ISNUMBER(SEARCH("Schott", _xlpm.EqName)), SQRT(_xlpm.Schott(_xlpm.λX)), NA() ) ) )} -> 1.4969993 | J3: {=_xlfn.LET( _xlpm.λX, _xlfn.SWITCH(INDEX($2:$2, COLUMN()), "nC", Addendum!$A$37/1000, "nd", Addendum!$A$46/1000, "ne", Addendum!$A$47/1000, "nF", Addendum!$A$62/1000, "ng", Addendum!$A$69/1000, ), _xlpm.EqName, INDEX($S:$S, ROW()), _xlpm.a_1, INDEX($T:$T, ROW()), _xlpm.a_2, INDEX($U:$U, ROW()), _xlpm.a_3, INDEX($V:$V, ROW()), _xlpm.a_4, INDEX($W:$W, ROW()), _xlpm.a_5, INDEX($X:$X, ROW()), _xlpm.a_6, INDEX($Y:$Y, ROW()), _xlpm.b_1, IF(ISNUMBER(SEARCH("Schott 3/4", _xlpm.EqName)), IFERROR(_xlfn.TEXTAFTER(INDEX($AE:$AE, ROW()), "="), 0), 0), _xlpm.Sellmeier, _xlfn.LAMBDA(_xlpm.λ, _xlpm.a_1*_xlpm.λ^2/(_xlpm.λ^2-_xlpm.a_4) + _xlpm.a_2*_xlpm.λ^2/(_xlpm.λ^2-_xlpm.a_5) + _xlpm.a_3*_xlpm.λ^2/(_xlpm.λ^2-_xlpm.a_6)), _xlpm.Schott, _xlfn.LAMBDA(_xlpm.λ, _xlpm.a_1 + _xlpm.a_2*(_xlpm.λ^2) + _xlpm.b_1*(_xlpm.λ^4) + _xlpm.a_3*(_xlpm.λ^-2) + _xlpm.a_4*(_xlpm.λ^-4) + _xlpm.a_5*(_xlpm.λ^-6) + _xlpm.a_6*(_xlpm.λ^-8)), IF(ISNUMBER(SEARCH("Sellmeier", _xlpm.EqName)), IF(ISNUMBER(SEARCH("Mod", _xlpm.EqName)), SQRT((2*_xlpm.Sellmeier(_xlpm.λX)+1)/(1-_xlpm.Sellmeier(_xlpm.λX))), SQRT(1+_xlpm.Sellmeier(_xlpm.λX)) ), IF(ISNUMBER(SEARCH("Schott", _xlpm.EqName)), SQRT(_xlpm.Schott(_xlpm.λX)), NA() ) ) )} -> 1.4984545 | K3: {=_xlfn.LET( _xlpm.λX, _xlfn.SWITCH(INDEX($2:$2, COLUMN()), "nC", Addendum!$A$37/1000, "nd", Addendum!$A$46/1000, "ne", Addendum!$A$47/1000, "nF", Addendum!$A$62/1000, "ng", Addendum!$A$69/1000, ), _xlpm.EqName, INDEX($S:$S, ROW()), _xlpm.a_1, INDEX($T:$T, ROW()), _xlpm.a_2, INDEX($U:$U, ROW()), _xlpm.a_3, INDEX($V:$V, ROW()), _xlpm.a_4, INDEX($W:$W, ROW()), _xlpm.a_5, INDEX($X:$X, ROW()), _xlpm.a_6, INDEX($Y:$Y, ROW()), _xlpm.b_1, IF(ISNUMBER(SEARCH("Schott 3/4", _xlpm.EqName)), IFERROR(_xlfn.TEXTAFTER(INDEX($AE:$AE, ROW()), "="), 0), 0), _xlpm.Sellmeier, _xlfn.LAMBDA(_xlpm.λ, _xlpm.a_1*_xlpm.λ^2/(_xlpm.λ^2-_xlpm.a_4) + _xlpm.a_2*_xlpm.λ^2/(_xlpm.λ^2-_xlpm.a_5) + _xlpm.a_3*_xlpm.λ^2/(_xlpm.λ^2-_xlpm.a_6)), _xlpm.Schott, _xlfn.LAMBDA(_xlpm.λ, _xlpm.a_1 + _xlpm.a_2*(_xlpm.λ^2) + _xlpm.b_1*(_xlpm.λ^4) + _xlpm.a_3*(_xlpm.λ^-2) + _xlpm.a_4*(_xlpm.λ^-4) + _xlpm.a_5*(_xlpm.λ^-6) + _xlpm.a_6*(_xlpm.λ^-8)), IF(ISNUMBER(SEARCH("Sellmeier", _xlpm.EqName)), IF(ISNUMBER(SEARCH("Mod", _xlpm.EqName)), SQRT((2*_xlpm.Sellmeier(_xlpm.λX)+1)/(1-_xlpm.Sellmeier(_xlpm.λX))), SQRT(1+_xlpm.Sellmeier(_xlpm.λX)) ), IF(ISNUMBER(SEARCH("Schott", _xlpm.EqName)), SQRT(_xlpm.Schott(_xlpm.λX)), NA() ) ) )} -> 1.5012311 | L3: {=_xlfn.LET( _xlpm.λX, _xlfn.SWITCH(INDEX($2:$2, COLUMN()), "nC", Addendum!$A$37/1000, "nd", Addendum!$A$46/1000, "ne", Addendum!$A$47/1000, "nF", Addendum!$A$62/1000, "ng", Addendum!$A$69/1000, ), _xlpm.EqName, INDEX($S:$S, ROW()), _xlpm.a_1, INDEX($T:$T, ROW()), _xlpm.a_2, INDEX($U:$U, ROW()), _xlpm.a_3, INDEX($V:$V, ROW()), _xlpm.a_4, INDEX($W:$W, ROW()), _xlpm.a_5, INDEX($X:$X, ROW()), _xlpm.a_6, INDEX($Y:$Y, ROW()), _xlpm.b_1, IF(ISNUMBER(SEARCH("Schott 3/4", _xlpm.EqName)), IFERROR(_xlfn.TEXTAFTER(INDEX($AE:$AE, ROW()), "="), 0), 0), _xlpm.Sellmeier, _xlfn.LAMBDA(_xlpm.λ, _xlpm.a_1*_xlpm.λ^2/(_xlpm.λ^2-_xlpm.a_4) + _xlpm.a_2*_xlpm.λ^2/(_xlpm.λ^2-_xlpm.a_5) + _xlpm.a_3*_xlpm.λ^2/(_xlpm.λ^2-_xlpm.a_6)), _xlpm.Schott, _xlfn.LAMBDA(_xlpm.λ, _xlpm.a_1 + _xlpm.a_2*(_xlpm.λ^2) + _xlpm.b_1*(_xlpm.λ^4) + _xlpm.a_3*(_xlpm.λ^-2) + _xlpm.a_4*(_xlpm.λ^-4) + _xlpm.a_5*(_xlpm.λ^-6) + _xlpm.a_6*(_xlpm.λ^-8)), IF(ISNUMBER(SEARCH("Sellmeier", _xlpm.EqName)), IF(ISNUMBER(SEARCH("Mod", _xlpm.EqName)), SQRT((2*_xlpm.Sellmeier(_xlpm.λX)+1)/(1-_xlpm.Sellmeier(_xlpm.λX))), SQRT(1+_xlpm.Sellmeier(_xlpm.λX)) ), IF(ISNUMBER(SEARCH("Schott", _xlpm.EqName)), SQRT(_xlpm.Schott(_xlpm.λX)), NA() ) ) )} -> 1.5045069 | M3: =K3-H3 -> 0.0060946477 | N3: =I3-H3 -> 0.0018628835 | O3: =L3-K3 -> 0.003275852 | P3: =(I3-H3)/M3 -> 0.30565892 | Q3: =(L3-K3)/M3 -> 0.53749652 | R3: 0.028 | S3: Sellmeier 3 | T3: 1.1701051 | U3: 0.047571078 | V3: 0.76383245 | W3: 0.0061620392 | X3: 0.026337288 | Y3: 141.88264 | Z3: 3.62 | AA3: 459 | AC3: Not Specified | AD3: Recommended
A4: 2 | B4: Ohara | C4: CaF | D4: S-FPL53 | E4: =I4 -> 1.4387504 | F4: =(I4-1)/M4 -> 94.947134 | G4: {=_xlfn.LET( _xlpm.λe, Addendum!$A$47/1000, _xlpm.λF, Addendum!$A$63/1000, _xlpm.λC, Addendum!$A$38/1000, _xlpm.EqName, INDEX($S:$S, ROW()), _xlpm.a_1, INDEX($T:$T, ROW()), _xlpm.a_2, INDEX($U:$U, ROW()), _xlpm.a_3, INDEX($V:$V, ROW()), _xlpm.a_4, INDEX($W:$W, ROW()), _xlpm.a_5, INDEX($X:$X, ROW()), _xlpm.a_6, INDEX($Y:$Y, ROW()), _xlpm.b_1, IF(ISNUMBER(SEARCH("Schott 3/4", _xlpm.EqName)), IFERROR(_xlfn.TEXTAFTER(INDEX($AE:$AE, ROW()), "="), 0), 0), _xlpm.Sellmeier, _xlfn.LAMBDA(_xlpm.λ, _xlpm.a_1*_xlpm.λ^2/(_xlpm.λ^2-_xlpm.a_4) + _xlpm.a_2*_xlpm.λ^2/(_xlpm.λ^2-_xlpm.a_5) + _xlpm.a_3*_xlpm.λ^2/(_xlpm.λ^2-_xlpm.a_6)), _xlpm.Schott, _xlfn.LAMBDA(_xlpm.λ, _xlpm.a_1 + _xlpm.a_2*(_xlpm.λ^2) + _xlpm.b_1*(_xlpm.λ^4) + _xlpm.a_3*(_xlpm.λ^-2) + _xlpm.a_4*(_xlpm.λ^-4) + _xlpm.a_5*(_xlpm.λ^-6) + _xlpm.a_6*(_xlpm.λ^-8)), _xlpm.RefrIndex, _xlfn.LAMBDA(_xlpm.λ, IF(ISNUMBER(SEARCH("Sellmeier", _xlpm.EqName)), IF(ISNUMBER(SEARCH("Mod", _xlpm.EqName)), SQRT((2*_xlpm.Sellmeier(_xlpm.λ)+1)/(1-_xlpm.Sellmeier(_xlpm.λ))), SQRT(1+_xlpm.Sellmeier(_xlpm.λ)) ), IF(ISNUMBER(SEARCH("Schott", _xlpm.EqName)), SQRT(_xlpm.Schott(_xlpm.λ)), NA() ) ) ), _xlpm.ne, _xlpm.RefrIndex(_xlpm.λe), _xlpm.nF, _xlpm.RefrIndex(_xlpm.λF), _xlpm.nC, _xlpm.RefrIndex(_xlpm.λC), (_xlpm.ne - 1)/(_xlpm.nF - _xlpm.nC) )} -> 94.494203 | H4: {=_xlfn.LET( _xlpm.λX, _xlfn.SWITCH(INDEX($2:$2, COLUMN()), "nC", Addendum!$A$37/1000, "nd", Addendum!$A$46/1000, "ne", Addendum!$A$47/1000, "nF", Addendum!$A$62/1000, "ng", Addendum!$A$69/1000, ), _xlpm.EqName, INDEX($S:$S, ROW()), _xlpm.a_1, INDEX($T:$T, ROW()), _xlpm.a_2, INDEX($U:$U, ROW()), _xlpm.a_3, INDEX($V:$V, ROW()), _xlpm.a_4, INDEX($W:$W, ROW()), _xlpm.a_5, INDEX($X:$X, ROW()), _xlpm.a_6, INDEX($Y:$Y, ROW()), _xlpm.b_1, IF(ISNUMBER(SEARCH("Schott 3/4", _xlpm.EqName)), IFERROR(_xlfn.TEXTAFTER(INDEX($AE:$AE, ROW()), "="), 0), 0), _xlpm.Sellmeier, _xlfn.LAMBDA(_xlpm.λ, _xlpm.a_1*_xlpm.λ^2/(_xlpm.λ^2-_xlpm.a_4) + _xlpm.a_2*_xlpm.λ^2/(_xlpm.λ^2-_xlpm.a_5) + _xlpm.a_3*_xlpm.λ^2/(_xlpm.λ^2-_xlpm.a_6)), _xlpm.Schott, _xlfn.LAMBDA(_xlpm.λ, _xlpm.a_1 + _xlpm.a_2*(_xlpm.λ^2) + _xlpm.b_1*(_xlpm.λ^4) + _xlpm.a_3*(_xlpm.λ^-2) + _xlpm.a_4*(_xlpm.λ^-4) + _xlpm.a_5*(_xlpm.λ^-6) + _xlpm.a_6*(_xlpm.λ^-8)), IF(ISNUMBER(SEARCH("Sellmeier", _xlpm.EqName)), IF(ISNUMBER(SEARCH("Mod", _xlpm.EqName)), SQRT((2*_xlpm.Sellmeier(_xlpm.λX)+1)/(1-_xlpm.Sellmeier(_xlpm.λX))), SQRT(1+_xlpm.Sellmeier(_xlpm.λX)) ), IF(ISNUMBER(SEARCH("Schott", _xlpm.EqName)), SQRT(_xlpm.Schott(_xlpm.λX)), NA() ) ) )} -> 1.4373334 | I4: {=_xlfn.LET( _xlpm.λX, _xlfn.SWITCH(INDEX($2:$2, COLUMN()), "nC", Addendum!$A$37/1000, "nd", Addendum!$A$46/1000, "ne", Addendum!$A$47/1000, "nF", Addendum!$A$62/1000, "ng", Addendum!$A$69/1000, ), _xlpm.EqName, INDEX($S:$S, ROW()), _xlpm.a_1, INDEX($T:$T, ROW()), _xlpm.a_2, INDEX($U:$U, ROW()), _xlpm.a_3, INDEX($V:$V, ROW()), _xlpm.a_4, INDEX($W:$W, ROW()), _xlpm.a_5, INDEX($X:$X, ROW()), _xlpm.a_6, INDEX($Y:$Y, ROW()), _xlpm.b_1, IF(ISNUMBER(SEARCH("Schott 3/4", _xlpm.EqName)), IFERROR(_xlfn.TEXTAFTER(INDEX($AE:$AE, ROW()), "="), 0), 0), _xlpm.Sellmeier, _xlfn.LAMBDA(_xlpm.λ, _xlpm.a_1*_xlpm.λ^2/(_xlpm.λ^2-_xlpm.a_4) + _xlpm.a_2*_xlpm.λ^2/(_xlpm.λ^2-_xlpm.a_5) + _xlpm.a_3*_xlpm.λ^2/(_xlpm.λ^2-_xlpm.a_6)), _xlpm.Schott, _xlfn.LAMBDA(_xlpm.λ, _xlpm.a_1 + _xlpm.a_2*(_xlpm.λ^2) + _xlpm.b_1*(_xlpm.λ^4) + _xlpm.a_3*(_xlpm.λ^-2) + _xlpm.a_4*(_xlpm.λ^-4) + _xlpm.a_5*(_xlpm.λ^-6) + _xlpm.a_6*(_xlpm.λ^-8)), IF(ISNUMBER(SEARCH("Sellmeier", _xlpm.EqName)), IF(ISNUMBER(SEARCH("Mod", _xlpm.EqName)), SQRT((2*_xlpm.Sellmeier(_xlpm.λX)+1)/(1-_xlpm.Sellmeier(_xlpm.λX))), SQRT(1+_xlpm.Sellmeier(_xlpm.λX)) ), IF(ISNUMBER(SEARCH("Schott", _xlpm.EqName)), SQRT(_xlpm.Schott(_xlpm.λX)), NA() ) ) )} -> 1.4387504 | J4: {=_xlfn.LET( _xlpm.λX, _xlfn.SWITCH(INDEX($2:$2, COLUMN()), "nC", Addendum!$A$37/1000, "nd", Addendum!$A$46/1000, "ne", Addendum!$A$47/1000, "nF", Addendum!$A$62/1000, "ng", Addendum!$A$69/1000, ), _xlpm.EqName, INDEX($S:$S, ROW()), _xlpm.a_1, INDEX($T:$T, ROW()), _xlpm.a_2, INDEX($U:$U, ROW()), _xlpm.a_3, INDEX($V:$V, ROW()), _xlpm.a_4, INDEX($W:$W, ROW()), _xlpm.a_5, INDEX($X:$X, ROW()), _xlpm.a_6, INDEX($Y:$Y, ROW()), _xlpm.b_1, IF(ISNUMBER(SEARCH("Schott 3/4", _xlpm.EqName)), IFERROR(_xlfn.TEXTAFTER(INDEX($AE:$AE, ROW()), "="), 0), 0), _xlpm.Sellmeier, _xlfn.LAMBDA(_xlpm.λ, _xlpm.a_1*_xlpm.λ^2/(_xlpm.λ^2-_xlpm.a_4) + _xlpm.a_2*_xlpm.λ^2/(_xlpm.λ^2-_xlpm.a_5) + _xlpm.a_3*_xlpm.λ^2/(_xlpm.λ^2-_xlpm.a_6)), _xlpm.Schott, _xlfn.LAMBDA(_xlpm.λ, _xlpm.a_1 + _xlpm.a_2*(_xlpm.λ^2) + _xlpm.b_1*(_xlpm.λ^4) + _xlpm.a_3*(_xlpm.λ^-2) + _xlpm.a_4*(_xlpm.λ^-4) + _xlpm.a_5*(_xlpm.λ^-6) + _xlpm.a_6*(_xlpm.λ^-8)), IF(ISNUMBER(SEARCH("Sellmeier", _xlpm.EqName)), IF(ISNUMBER(SEARCH("Mod", _xlpm.EqName)), SQRT((2*_xlpm.Sellmeier(_xlpm.λX)+1)/(1-_xlpm.Sellmeier(_xlpm.λX))), SQRT(1+_xlpm.Sellmeier(_xlpm.λX)) ), IF(ISNUMBER(SEARCH("Schott", _xlpm.EqName)), SQRT(_xlpm.Schott(_xlpm.λX)), NA() ) ) )} -> 1.4398542 | K4: {=_xlfn.LET( _xlpm.λX, _xlfn.SWITCH(INDEX($2:$2, COLUMN()), "nC", Addendum!$A$37/1000, "nd", Addendum!$A$46/1000, "ne", Addendum!$A$47/1000, "nF", Addendum!$A$62/1000, "ng", Addendum!$A$69/1000, ), _xlpm.EqName, INDEX($S:$S, ROW()), _xlpm.a_1, INDEX($T:$T, ROW()), _xlpm.a_2, INDEX($U:$U, ROW()), _xlpm.a_3, INDEX($V:$V, ROW()), _xlpm.a_4, INDEX($W:$W, ROW()), _xlpm.a_5, INDEX($X:$X, ROW()), _xlpm.a_6, INDEX($Y:$Y, ROW()), _xlpm.b_1, IF(ISNUMBER(SEARCH("Schott 3/4", _xlpm.EqName)), IFERROR(_xlfn.TEXTAFTER(INDEX($AE:$AE, ROW()), "="), 0), 0), _xlpm.Sellmeier, _xlfn.LAMBDA(_xlpm.λ, _xlpm.a_1*_xlpm.λ^2/(_xlpm.λ^2-_xlpm.a_4) + _xlpm.a_2*_xlpm.λ^2/(_xlpm.λ^2-_xlpm.a_5) + _xlpm.a_3*_xlpm.λ^2/(_xlpm.λ^2-_xlpm.a_6)), _xlpm.Schott, _xlfn.LAMBDA(_xlpm.λ, _xlpm.a_1 + _xlpm.a_2*(_xlpm.λ^2) + _xlpm.b_1*(_xlpm.λ^4) + _xlpm.a_3*(_xlpm.λ^-2) + _xlpm.a_4*(_xlpm.λ^-4) + _xlpm.a_5*(_xlpm.λ^-6) + _xlpm.a_6*(_xlpm.λ^-8)), IF(ISNUMBER(SEARCH("Sellmeier", _xlpm.EqName)), IF(ISNUMBER(SEARCH("Mod", _xlpm.EqName)), SQRT((2*_xlpm.Sellmeier(_xlpm.λX)+1)/(1-_xlpm.Sellmeier(_xlpm.λX))), SQRT(1+_xlpm.Sellmeier(_xlpm.λX)) ), IF(ISNUMBER(SEARCH("Schott", _xlpm.EqName)), SQRT(_xlpm.Schott(_xlpm.λX)), NA() ) ) )} -> 1.4419544 | L4: {=_xlfn.LET( _xlpm.λX, _xlfn.SWITCH(INDEX($2:$2, COLUMN()), "nC", Addendum!$A$37/1000, "nd", Addendum!$A$46/1000, "ne", Addendum!$A$47/1000, "nF", Addendum!$A$62/1000, "ng", Addendum!$A$69/1000, ), _xlpm.EqName, INDEX($S:$S, ROW()), _xlpm.a_1, INDEX($T:$T, ROW()), _xlpm.a_2, INDEX($U:$U, ROW()), _xlpm.a_3, INDEX($V:$V, ROW()), _xlpm.a_4, INDEX($W:$W, ROW()), _xlpm.a_5, INDEX($X:$X, ROW()), _xlpm.a_6, INDEX($Y:$Y, ROW()), _xlpm.b_1, IF(ISNUMBER(SEARCH("Schott 3/4", _xlpm.EqName)), IFERROR(_xlfn.TEXTAFTER(INDEX($AE:$AE, ROW()), "="), 0), 0), _xlpm.Sellmeier, _xlfn.LAMBDA(_xlpm.λ, _xlpm.a_1*_xlpm.λ^2/(_xlpm.λ^2-_xlpm.a_4) + _xlpm.a_2*_xlpm.λ^2/(_xlpm.λ^2-_xlpm.a_5) + _xlpm.a_3*_xlpm.λ^2/(_xlpm.λ^2-_xlpm.a_6)), _xlpm.Schott, _xlfn.LAMBDA(_xlpm.λ, _xlpm.a_1 + _xlpm.a_2*(_xlpm.λ^2) + _xlpm.b_1*(_xlpm.λ^4) + _xlpm.a_3*(_xlpm.λ^-2) + _xlpm.a_4*(_xlpm.λ^-4) + _xlpm.a_5*(_xlpm.λ^-6) + _xlpm.a_6*(_xlpm.λ^-8)), IF(ISNUMBER(SEARCH("Sellmeier", _xlpm.EqName)), IF(ISNUMBER(SEARCH("Mod", _xlpm.EqName)), SQRT((2*_xlpm.Sellmeier(_xlpm.λX)+1)/(1-_xlpm.Sellmeier(_xlpm.λX))), SQRT(1+_xlpm.Sellmeier(_xlpm.λX)) ), IF(ISNUMBER(SEARCH("Schott", _xlpm.EqName)), SQRT(_xlpm.Schott(_xlpm.λX)), NA() ) ) )} -> 1.4444235 | M4: =K4-H4 -> 0.0046209971 | N4: =I4-H4 -> 0.0014170795 | O4: =L4-K4 -> 0.0024691924 | P4: =(I4-H4)/M4 -> 0.30666097 | Q4: =(L4-K4)/M4 -> 0.53434191 | R4: 0.0461 | S4: Sellmeier 3 | T4: 0.98353233 | U4: 0.069568814 | V4: 1.1140924 | W4: 0.0049223495 | X4: 0.019358109 | Y4: 264.27529 | Z4: 3.62 | AA4: 428 | AC4: Not Specified | AD4: Recommended
A5: 3 | B5: Ohara | C5: CaF | D5: S-FPL55 | E5: =I5 -> 1.4387496 | F5: =(I5-1)/M5 -> 94.662165 | G5: {=_xlfn.LET( _xlpm.λe, Addendum!$A$47/1000, _xlpm.λF, Addendum!$A$63/1000, _xlpm.λC, Addendum!$A$38/1000, _xlpm.EqName, INDEX($S:$S, ROW()), _xlpm.a_1, INDEX($T:$T, ROW()), _xlpm.a_2, INDEX($U:$U, ROW()), _xlpm.a_3, INDEX($V:$V, ROW()), _xlpm.a_4, INDEX($W:$W, ROW()), _xlpm.a_5, INDEX($X:$X, ROW()), _xlpm.a_6, INDEX($Y:$Y, ROW()), _xlpm.b_1, IF(ISNUMBER(SEARCH("Schott 3/4", _xlpm.EqName)), IFERROR(_xlfn.TEXTAFTER(INDEX($AE:$AE, ROW()), "="), 0), 0), _xlpm.Sellmeier, _xlfn.LAMBDA(_xlpm.λ, _xlpm.a_1*_xlpm.λ^2/(_xlpm.λ^2-_xlpm.a_4) + _xlpm.a_2*_xlpm.λ^2/(_xlpm.λ^2-_xlpm.a_5) + _xlpm.a_3*_xlpm.λ^2/(_xlpm.λ^2-_xlpm.a_6)), _xlpm.Schott, _xlfn.LAMBDA(_xlpm.λ, _xlpm.a_1 + _xlpm.a_2*(_xlpm.λ^2) + _xlpm.b_1*(_xlpm.λ^4) + _xlpm.a_3*(_xlpm.λ^-2) + _xlpm.a_4*(_xlpm.λ^-4) + _xlpm.a_5*(_xlpm.λ^-6) + _xlpm.a_6*(_xlpm.λ^-8)), _xlpm.RefrIndex, _xlfn.LAMBDA(_xlpm.λ, IF(ISNUMBER(SEARCH("Sellmeier", _xlpm.EqName)), IF(ISNUMBER(SEARCH("Mod", _xlpm.EqName)), SQRT((2*_xlpm.Sellmeier(_xlpm.λ)+1)/(1-_xlpm.Sellmeier(_xlpm.λ))), SQRT(1+_xlpm.Sellmeier(_xlpm.λ)) ), IF(ISNUMBER(SEARCH("Schott", _xlpm.EqName)), SQRT(_xlpm.Schott(_xlpm.λ)), NA() ) ) ), _xlpm.ne, _xlpm.RefrIndex(_xlpm.λe), _xlpm.nF, _xlpm.RefrIndex(_xlpm.λF), _xlpm.nC, _xlpm.RefrIndex(_xlpm.λC), (_xlpm.ne - 1)/(_xlpm.nF - _xlpm.nC) )} -> 94.217195 | H5: {=_xlfn.LET( _xlpm.λX, _xlfn.SWITCH(INDEX($2:$2, COLUMN()), "nC", Addendum!$A$37/1000, "nd", Addendum!$A$46/1000, "ne", Addendum!$A$47/1000, "nF", Addendum!$A$62/1000, "ng", Addendum!$A$69/1000, ), _xlpm.EqName, INDEX($S:$S, ROW()), _xlpm.a_1, INDEX($T:$T, ROW()), _xlpm.a_2, INDEX($U:$U, ROW()), _xlpm.a_3, INDEX($V:$V, ROW()), _xlpm.a_4, INDEX($W:$W, ROW()), _xlpm.a_5, INDEX($X:$X, ROW()), _xlpm.a_6, INDEX($Y:$Y, ROW()), _xlpm.b_1, IF(ISNUMBER(SEARCH("Schott 3/4", _xlpm.EqName)), IFERROR(_xlfn.TEXTAFTER(INDEX($AE:$AE, ROW()), "="), 0), 0), _xlpm.Sellmeier, _xlfn.LAMBDA(_xlpm.λ, _xlpm.a_1*_xlpm.λ^2/(_xlpm.λ^2-_xlpm.a_4) + _xlpm.a_2*_xlpm.λ^2/(_xlpm.λ^2-_xlpm.a_5) + _xlpm.a_3*_xlpm.λ^2/(_xlpm.λ^2-_xlpm.a_6)), _xlpm.Schott, _xlfn.LAMBDA(_xlpm.λ, _xlpm.a_1 + _xlpm.a_2*(_xlpm.λ^2) + _xlpm.b_1*(_xlpm.λ^4) + _xlpm.a_3*(_xlpm.λ^-2) + _xlpm.a_4*(_xlpm.λ^-4) + _xlpm.a_5*(_xlpm.λ^-6) + _xlpm.a_6*(_xlpm.λ^-8)), IF(ISNUMBER(SEARCH("Sellmeier", _xlpm.EqName)), IF(ISNUMBER(SEARCH("Mod", _xlpm.EqName)), SQRT((2*_xlpm.Sellmeier(_xlpm.λX)+1)/(1-_xlpm.Sellmeier(_xlpm.λX))), SQRT(1+_xlpm.Sellmeier(_xlpm.λX)) ), IF(ISNUMBER(SEARCH("Schott", _xlpm.EqName)), SQRT(_xlpm.Schott(_xlpm.λX)), NA() ) ) )} -> 1.4373276 | I5: {=_xlfn.LET( _xlpm.λX, _xlfn.SWITCH(INDEX($2:$2, COLUMN()), "nC", Addendum!$A$37/1000, "nd", Addendum!$A$46/1000, "ne", Addendum!$A$47/1000, "nF", Addendum!$A$62/1000, "ng", Addendum!$A$69/1000, ), _xlpm.EqName, INDEX($S:$S, ROW()), _xlpm.a_1, INDEX($T:$T, ROW()), _xlpm.a_2, INDEX($U:$U, ROW()), _xlpm.a_3, INDEX($V:$V, ROW()), _xlpm.a_4, INDEX($W:$W, ROW()), _xlpm.a_5, INDEX($X:$X, ROW()), _xlpm.a_6, INDEX($Y:$Y, ROW()), _xlpm.b_1, IF(ISNUMBER(SEARCH("Schott 3/4", _xlpm.EqName)), IFERROR(_xlfn.TEXTAFTER(INDEX($AE:$AE, ROW()), "="), 0), 0), _xlpm.Sellmeier, _xlfn.LAMBDA(_xlpm.λ, _xlpm.a_1*_xlpm.λ^2/(_xlpm.λ^2-_xlpm.a_4) + _xlpm.a_2*_xlpm.λ^2/(_xlpm.λ^2-_xlpm.a_5) + _xlpm.a_3*_xlpm.λ^2/(_xlpm.λ^2-_xlpm.a_6)), _xlpm.Schott, _xlfn.LAMBDA(_xlpm.λ, _xlpm.a_1 + _xlpm.a_2*(_xlpm.λ^2) + _xlpm.b_1*(_xlpm.λ^4) + _xlpm.a_3*(_xlpm.λ^-2) + _xlpm.a_4*(_xlpm.λ^-4) + _xlpm.a_5*(_xlpm.λ^-6) + _xlpm.a_6*(_xlpm.λ^-8)), IF(ISNUMBER(SEARCH("Sellmeier", _xlpm.EqName)), IF(ISNUMBER(SEARCH("Mod", _xlpm.EqName)), SQRT((2*_xlpm.Sellmeier(_xlpm.λX)+1)/(1-_xlpm.Sellmeier(_xlpm.λX))), SQRT(1+_xlpm.Sellmeier(_xlpm.λX)) ), IF(ISNUMBER(SEARCH("Schott", _xlpm.EqName)), SQRT(_xlpm.Schott(_xlpm.λX)), NA() ) ) )} -> 1.4387496 | J5: {=_xlfn.LET( _xlpm.λX, _xlfn.SWITCH(INDEX($2:$2, COLUMN()), "nC", Addendum!$A$37/1000, "nd", Addendum!$A$46/1000, "ne", Addendum!$A$47/1000, "nF", Addendum!$A$62/1000, "ng", Addendum!$A$69/1000, ), _xlpm.EqName, INDEX($S:$S, ROW()), _xlpm.a_1, INDEX($T:$T, ROW()), _xlpm.a_2, INDEX($U:$U, ROW()), _xlpm.a_3, INDEX($V:$V, ROW()), _xlpm.a_4, INDEX($W:$W, ROW()), _xlpm.a_5, INDEX($X:$X, ROW()), _xlpm.a_6, INDEX($Y:$Y, ROW()), _xlpm.b_1, IF(ISNUMBER(SEARCH("Schott 3/4", _xlpm.EqName)), IFERROR(_xlfn.TEXTAFTER(INDEX($AE:$AE, ROW()), "="), 0), 0), _xlpm.Sellmeier, _xlfn.LAMBDA(_xlpm.λ, _xlpm.a_1*_xlpm.λ^2/(_xlpm.λ^2-_xlpm.a_4) + _xlpm.a_2*_xlpm.λ^2/(_xlpm.λ^2-_xlpm.a_5) + _xlpm.a_3*_xlpm.λ^2/(_xlpm.λ^2-_xlpm.a_6)), _xlpm.Schott, _xlfn.LAMBDA(_xlpm.λ, _xlpm.a_1 + _xlpm.a_2*(_xlpm.λ^2) + _xlpm.b_1*(_xlpm.λ^4) + _xlpm.a_3*(_xlpm.λ^-2) + _xlpm.a_4*(_xlpm.λ^-4) + _xlpm.a_5*(_xlpm.λ^-6) + _xlpm.a_6*(_xlpm.λ^-8)), IF(ISNUMBER(SEARCH("Sellmeier", _xlpm.EqName)), IF(ISNUMBER(SEARCH("Mod", _xlpm.EqName)), SQRT((2*_xlpm.Sellmeier(_xlpm.λX)+1)/(1-_xlpm.Sellmeier(_xlpm.λX))), SQRT(1+_xlpm.Sellmeier(_xlpm.λX)) ), IF(ISNUMBER(SEARCH("Schott", _xlpm.EqName)), SQRT(_xlpm.Schott(_xlpm.λX)), NA() ) ) )} -> 1.4398566 | K5: {=_xlfn.LET( _xlpm.λX, _xlfn.SWITCH(INDEX($2:$2, COLUMN()), "nC", Addendum!$A$37/1000, "nd", Addendum!$A$46/1000, "ne", Addendum!$A$47/1000, "nF", Addendum!$A$62/1000, "ng", Addendum!$A$69/1000, ), _xlpm.EqName, INDEX($S:$S, ROW()), _xlpm.a_1, INDEX($T:$T, ROW()), _xlpm.a_2, INDEX($U:$U, ROW()), _xlpm.a_3, INDEX($V:$V, ROW()), _xlpm.a_4, INDEX($W:$W, ROW()), _xlpm.a_5, INDEX($X:$X, ROW()), _xlpm.a_6, INDEX($Y:$Y, ROW()), _xlpm.b_1, IF(ISNUMBER(SEARCH("Schott 3/4", _xlpm.EqName)), IFERROR(_xlfn.TEXTAFTER(INDEX($AE:$AE, ROW()), "="), 0), 0), _xlpm.Sellmeier, _xlfn.LAMBDA(_xlpm.λ, _xlpm.a_1*_xlpm.λ^2/(_xlpm.λ^2-_xlpm.a_4) + _xlpm.a_2*_xlpm.λ^2/(_xlpm.λ^2-_xlpm.a_5) + _xlpm.a_3*_xlpm.λ^2/(_xlpm.λ^2-_xlpm.a_6)), _xlpm.Schott, _xlfn.LAMBDA(_xlpm.λ, _xlpm.a_1 + _xlpm.a_2*(_xlpm.λ^2) + _xlpm.b_1*(_xlpm.λ^4) + _xlpm.a_3*(_xlpm.λ^-2) + _xlpm.a_4*(_xlpm.λ^-4) + _xlpm.a_5*(_xlpm.λ^-6) + _xlpm.a_6*(_xlpm.λ^-8)), IF(ISNUMBER(SEARCH("Sellmeier", _xlpm.EqName)), IF(ISNUMBER(SEARCH("Mod", _xlpm.EqName)), SQRT((2*_xlpm.Sellmeier(_xlpm.λX)+1)/(1-_xlpm.Sellmeier(_xlpm.λX))), SQRT(1+_xlpm.Sellmeier(_xlpm.λX)) ), IF(ISNUMBER(SEARCH("Schott", _xlpm.EqName)), SQRT(_xlpm.Schott(_xlpm.λX)), NA() ) ) )} -> 1.4419625 | L5: {=_xlfn.LET( _xlpm.λX, _xlfn.SWITCH(INDEX($2:$2, COLUMN()), "nC", Addendum!$A$37/1000, "nd", Addendum!$A$46/1000, "ne", Addendum!$A$47/1000, "nF", Addendum!$A$62/1000, "ng", Addendum!$A$69/1000, ), _xlpm.EqName, INDEX($S:$S, ROW()), _xlpm.a_1, INDEX($T:$T, ROW()), _xlpm.a_2, INDEX($U:$U, ROW()), _xlpm.a_3, INDEX($V:$V, ROW()), _xlpm.a_4, INDEX($W:$W, ROW()), _xlpm.a_5, INDEX($X:$X, ROW()), _xlpm.a_6, INDEX($Y:$Y, ROW()), _xlpm.b_1, IF(ISNUMBER(SEARCH("Schott 3/4", _xlpm.EqName)), IFERROR(_xlfn.TEXTAFTER(INDEX($AE:$AE, ROW()), "="), 0), 0), _xlpm.Sellmeier, _xlfn.LAMBDA(_xlpm.λ, _xlpm.a_1*_xlpm.λ^2/(_xlpm.λ^2-_xlpm.a_4) + _xlpm.a_2*_xlpm.λ^2/(_xlpm.λ^2-_xlpm.a_5) + _xlpm.a_3*_xlpm.λ^2/(_xlpm.λ^2-_xlpm.a_6)), _xlpm.Schott, _xlfn.LAMBDA(_xlpm.λ, _xlpm.a_1 + _xlpm.a_2*(_xlpm.λ^2) + _xlpm.b_1*(_xlpm.λ^4) + _xlpm.a_3*(_xlpm.λ^-2) + _xlpm.a_4*(_xlpm.λ^-4) + _xlpm.a_5*(_xlpm.λ^-6) + _xlpm.a_6*(_xlpm.λ^-8)), IF(ISNUMBER(SEARCH("Sellmeier", _xlpm.EqName)), IF(ISNUMBER(SEARCH("Mod", _xlpm.EqName)), SQRT((2*_xlpm.Sellmeier(_xlpm.λX)+1)/(1-_xlpm.Sellmeier(_xlpm.λX))), SQRT(1+_xlpm.Sellmeier(_xlpm.λX)) ), IF(ISNUMBER(SEARCH("Schott", _xlpm.EqName)), SQRT(_xlpm.Schott(_xlpm.λX)), NA() ) ) )} -> 1.4444377 | M5: =K5-H5 -> 0.0046348988 | N5: =I5-H5 -> 0.0014219863 | O5: =L5-K5 -> 0.0024752031 | P5: =(I5-H5)/M5 -> 0.30679986 | Q5: =(L5-K5)/M5 -> 0.53403607 | R5: 0.0457 | S5: Sellmeier 3 | T5: 0.83906768 | U5: 0.2140835 | V5: 1.4791468 | W5: 0.0079528664 | X5: -0.0023258172 | Y5: 340.0437 | Z5: 3.59 | AA5: 439 | AC5: Not Specified | AD5: Recommended
A6: 4 | B6: Ohara | C6: CaF | D6: S-FPM 2 | E6: =I6 -> 1.5952196 | F6: =(I6-1)/M6 -> 67.736526 | G6: {=_xlfn.LET( _xlpm.λe, Addendum!$A$47/1000, _xlpm.λF, Addendum!$A$63/1000, _xlpm.λC, Addendum!$A$38/1000, _xlpm.EqName, INDEX($S:$S, ROW()), _xlpm.a_1, INDEX($T:$T, ROW()), _xlpm.a_2, INDEX($U:$U, ROW()), _xlpm.a_3, INDEX($V:$V, ROW()), _xlpm.a_4, INDEX($W:$W, ROW()), _xlpm.a_5, INDEX($X:$X, ROW()), _xlpm.a_6, INDEX($Y:$Y, ROW()), _xlpm.b_1, IF(ISNUMBER(SEARCH("Schott 3/4", _xlpm.EqName)), IFERROR(_xlfn.TEXTAFTER(INDEX($AE:$AE, ROW()), "="), 0), 0), _xlpm.Sellmeier, _xlfn.LAMBDA(_xlpm.λ, _xlpm.a_1*_xlpm.λ^2/(_xlpm.λ^2-_xlpm.a_4) + _xlpm.a_2*_xlpm.λ^2/(_xlpm.λ^2-_xlpm.a_5) + _xlpm.a_3*_xlpm.λ^2/(_xlpm.λ^2-_xlpm.a_6)), _xlpm.Schott, _xlfn.LAMBDA(_xlpm.λ, _xlpm.a_1 + _xlpm.a_2*(_xlpm.λ^2) + _xlpm.b_1*(_xlpm.λ^4) + _xlpm.a_3*(_xlpm.λ^-2) + _xlpm.a_4*(_xlpm.λ^-4) + _xlpm.a_5*(_xlpm.λ^-6) + _xlpm.a_6*(_xlpm.λ^-8)), _xlpm.RefrIndex, _xlfn.LAMBDA(_xlpm.λ, IF(ISNUMBER(SEARCH("Sellmeier", _xlpm.EqName)), IF(ISNUMBER(SEARCH("Mod", _xlpm.EqName)), SQRT((2*_xlpm.Sellmeier(_xlpm.λ)+1)/(1-_xlpm.Sellmeier(_xlpm.λ))), SQRT(1+_xlpm.Sellmeier(_xlpm.λ)) ), IF(ISNUMBER(SEARCH("Schott", _xlpm.EqName)), SQRT(_xlpm.Schott(_xlpm.λ)), NA() ) ) ), _xlpm.ne, _xlpm.RefrIndex(_xlpm.λe), _xlpm.nF, _xlpm.RefrIndex(_xlpm.λF), _xlpm.nC, _xlpm.RefrIndex(_xlpm.λC), (_xlpm.ne - 1)/(_xlpm.nF - _xlpm.nC) )} -> 67.374295 | H6: {=_xlfn.LET( _xlpm.λX, _xlfn.SWITCH(INDEX($2:$2, COLUMN()), "nC", Addendum!$A$37/1000, "nd", Addendum!$A$46/1000, "ne", Addendum!$A$47/1000, "nF", Addendum!$A$62/1000, "ng", Addendum!$A$69/1000, ), _xlpm.EqName, INDEX($S:$S, ROW()), _xlpm.a_1, INDEX($T:$T, ROW()), _xlpm.a_2, INDEX($U:$U, ROW()), _xlpm.a_3, INDEX($V:$V, ROW()), _xlpm.a_4, INDEX($W:$W, ROW()), _xlpm.a_5, INDEX($X:$X, ROW()), _xlpm.a_6, INDEX($Y:$Y, ROW()), _xlpm.b_1, IF(ISNUMBER(SEARCH("Schott 3/4", _xlpm.EqName)), IFERROR(_xlfn.TEXTAFTER(INDEX($AE:$AE, ROW()), "="), 0), 0), _xlpm.Sellmeier, _xlfn.LAMBDA(_xlpm.λ, _xlpm.a_1*_xlpm.λ^2/(_xlpm.λ^2-_xlpm.a_4) + _xlpm.a_2*_xlpm.λ^2/(_xlpm.λ^2-_xlpm.a_5) + _xlpm.a_3*_xlpm.λ^2/(_xlpm.λ^2-_xlpm.a_6)), _xlpm.Schott, _xlfn.LAMBDA(_xlpm.λ, _xlpm.a_1 + _xlpm.a_2*(_xlpm.λ^2) + _xlpm.b_1*(_xlpm.λ^4) + _xlpm.a_3*(_xlpm.λ^-2) + _xlpm.a_4*(_xlpm.λ^-4) + _xlpm.a_5*(_xlpm.λ^-6) + _xlpm.a_6*(_xlpm.λ^-8)), IF(ISNUMBER(SEARCH("Sellmeier", _xlpm.EqName)), IF(ISNUMBER(SEARCH("Mod", _xlpm.EqName)), SQRT((2*_xlpm.Sellmeier(_xlpm.λX)+1)/(1-_xlpm.Sellmeier(_xlpm.λX))), SQRT(1+_xlpm.Sellmeier(_xlpm.λX)) ), IF(ISNUMBER(SEARCH("Schott", _xlpm.EqName)), SQRT(_xlpm.Schott(_xlpm.λX)), NA() ) ) )} -> 1.5925546 | I6: {=_xlfn.LET( _xlpm.λX, _xlfn.SWITCH(INDEX($2:$2, COLUMN()), "nC", Addendum!$A$37/1000, "nd", Addendum!$A$46/1000, "ne", Addendum!$A$47/1000, "nF", Addendum!$A$62/1000, "ng", Addendum!$A$69/1000, ), _xlpm.EqName, INDEX($S:$S, ROW()), _xlpm.a_1, INDEX($T:$T, ROW()), _xlpm.a_2, INDEX($U:$U, ROW()), _xlpm.a_3, INDEX($V:$V, ROW()), _xlpm.a_4, INDEX($W:$W, ROW()), _xlpm.a_5, INDEX($X:$X, ROW()), _xlpm.a_6, INDEX($Y:$Y, ROW()), _xlpm.b_1, IF(ISNUMBER(SEARCH("Schott 3/4", _xlpm.EqName)), IFERROR(_xlfn.TEXTAFTER(INDEX($AE:$AE, ROW()), "="), 0), 0), _xlpm.Sellmeier, _xlfn.LAMBDA(_xlpm.λ, _xlpm.a_1*_xlpm.λ^2/(_xlpm.λ^2-_xlpm.a_4) + _xlpm.a_2*_xlpm.λ^2/(_xlpm.λ^2-_xlpm.a_5) + _xlpm.a_3*_xlpm.λ^2/(_xlpm.λ^2-_xlpm.a_6)), _xlpm.Schott, _xlfn.LAMBDA(_xlpm.λ, _xlpm.a_1 + _xlpm.a_2*(_xlpm.λ^2) + _xlpm.b_1*(_xlpm.λ^4) + _xlpm.a_3*(_xlpm.λ^-2) + _xlpm.a_4*(_xlpm.λ^-4) + _xlpm.a_5*(_xlpm.λ^-6) + _xlpm.a_6*(_xlpm.λ^-8)), IF(ISNUMBER(SEARCH("Sellmeier", _xlpm.EqName)), IF(ISNUMBER(SEARCH("Mod", _xlpm.EqName)), SQRT((2*_xlpm.Sellmeier(_xlpm.λX)+1)/(1-_xlpm.Sellmeier(_xlpm.λX))), SQRT(1+_xlpm.Sellmeier(_xlpm.λX)) ), IF(ISNUMBER(SEARCH("Schott", _xlpm.EqName)), SQRT(_xlpm.Schott(_xlpm.λX)), NA() ) ) )} -> 1.5952196 | J6: {=_xlfn.LET( _xlpm.λX, _xlfn.SWITCH(INDEX($2:$2, COLUMN()), "nC", Addendum!$A$37/1000, "nd", Addendum!$A$46/1000, "ne", Addendum!$A$47/1000, "nF", Addendum!$A$62/1000, "ng", Addendum!$A$69/1000, ), _xlpm.EqName, INDEX($S:$S, ROW()), _xlpm.a_1, INDEX($T:$T, ROW()), _xlpm.a_2, INDEX($U:$U, ROW()), _xlpm.a_3, INDEX($V:$V, ROW()), _xlpm.a_4, INDEX($W:$W, ROW()), _xlpm.a_5, INDEX($X:$X, ROW()), _xlpm.a_6, INDEX($Y:$Y, ROW()), _xlpm.b_1, IF(ISNUMBER(SEARCH("Schott 3/4", _xlpm.EqName)), IFERROR(_xlfn.TEXTAFTER(INDEX($AE:$AE, ROW()), "="), 0), 0), _xlpm.Sellmeier, _xlfn.LAMBDA(_xlpm.λ, _xlpm.a_1*_xlpm.λ^2/(_xlpm.λ^2-_xlpm.a_4) + _xlpm.a_2*_xlpm.λ^2/(_xlpm.λ^2-_xlpm.a_5) + _xlpm.a_3*_xlpm.λ^2/(_xlpm.λ^2-_xlpm.a_6)), _xlpm.Schott, _xlfn.LAMBDA(_xlpm.λ, _xlpm.a_1 + _xlpm.a_2*(_xlpm.λ^2) + _xlpm.b_1*(_xlpm.λ^4) + _xlpm.a_3*(_xlpm.λ^-2) + _xlpm.a_4*(_xlpm.λ^-4) + _xlpm.a_5*(_xlpm.λ^-6) + _xlpm.a_6*(_xlpm.λ^-8)), IF(ISNUMBER(SEARCH("Sellmeier", _xlpm.EqName)), IF(ISNUMBER(SEARCH("Mod", _xlpm.EqName)), SQRT((2*_xlpm.Sellmeier(_xlpm.λX)+1)/(1-_xlpm.Sellmeier(_xlpm.λX))), SQRT(1+_xlpm.Sellmeier(_xlpm.λX)) ), IF(ISNUMBER(SEARCH("Schott", _xlpm.EqName)), SQRT(_xlpm.Schott(_xlpm.λX)), NA() ) ) )} -> 1.597316 | K6: {=_xlfn.LET( _xlpm.λX, _xlfn.SWITCH(INDEX($2:$2, COLUMN()), "nC", Addendum!$A$37/1000, "nd", Addendum!$A$46/1000, "ne", Addendum!$A$47/1000, "nF", Addendum!$A$62/1000, "ng", Addendum!$A$69/1000, ), _xlpm.EqName, INDEX($S:$S, ROW()), _xlpm.a_1, INDEX($T:$T, ROW()), _xlpm.a_2, INDEX($U:$U, ROW()), _xlpm.a_3, INDEX($V:$V, ROW()), _xlpm.a_4, INDEX($W:$W, ROW()), _xlpm.a_5, INDEX($X:$X, ROW()), _xlpm.a_6, INDEX($Y:$Y, ROW()), _xlpm.b_1, IF(ISNUMBER(SEARCH("Schott 3/4", _xlpm.EqName)), IFERROR(_xlfn.TEXTAFTER(INDEX($AE:$AE, ROW()), "="), 0), 0), _xlpm.Sellmeier, _xlfn.LAMBDA(_xlpm.λ, _xlpm.a_1*_xlpm.λ^2/(_xlpm.λ^2-_xlpm.a_4) + _xlpm.a_2*_xlpm.λ^2/(_xlpm.λ^2-_xlpm.a_5) + _xlpm.a_3*_xlpm.λ^2/(_xlpm.λ^2-_xlpm.a_6)), _xlpm.Schott, _xlfn.LAMBDA(_xlpm.λ, _xlpm.a_1 + _xlpm.a_2*(_xlpm.λ^2) + _xlpm.b_1*(_xlpm.λ^4) + _xlpm.a_3*(_xlpm.λ^-2) + _xlpm.a_4*(_xlpm.λ^-4) + _xlpm.a_5*(_xlpm.λ^-6) + _xlpm.a_6*(_xlpm.λ^-8)), IF(ISNUMBER(SEARCH("Sellmeier", _xlpm.EqName)), IF(ISNUMBER(SEARCH("Mod", _xlpm.EqName)), SQRT((2*_xlpm.Sellmeier(_xlpm.λX)+1)/(1-_xlpm.Sellmeier(_xlpm.λX))), SQRT(1+_xlpm.Sellmeier(_xlpm.λX)) ), IF(ISNUMBER(SEARCH("Schott", _xlpm.EqName)), SQRT(_xlpm.Schott(_xlpm.λX)), NA() ) ) )} -> 1.6013419 | L6: {=_xlfn.LET( _xlpm.λX, _xlfn.SWITCH(INDEX($2:$2, COLUMN()), "nC", Addendum!$A$37/1000, "nd", Addendum!$A$46/1000, "ne", Addendum!$A$47/1000, "nF", Addendum!$A$62/1000, "ng", Addendum!$A$69/1000, ), _xlpm.EqName, INDEX($S:$S, ROW()), _xlpm.a_1, INDEX($T:$T, ROW()), _xlpm.a_2, INDEX($U:$U, ROW()), _xlpm.a_3, INDEX($V:$V, ROW()), _xlpm.a_4, INDEX($W:$W, ROW()), _xlpm.a_5, INDEX($X:$X, ROW()), _xlpm.a_6, INDEX($Y:$Y, ROW()), _xlpm.b_1, IF(ISNUMBER(SEARCH("Schott 3/4", _xlpm.EqName)), IFERROR(_xlfn.TEXTAFTER(INDEX($AE:$AE, ROW()), "="), 0), 0), _xlpm.Sellmeier, _xlfn.LAMBDA(_xlpm.λ, _xlpm.a_1*_xlpm.λ^2/(_xlpm.λ^2-_xlpm.a_4) + _xlpm.a_2*_xlpm.λ^2/(_xlpm.λ^2-_xlpm.a_5) + _xlpm.a_3*_xlpm.λ^2/(_xlpm.λ^2-_xlpm.a_6)), _xlpm.Schott, _xlfn.LAMBDA(_xlpm.λ, _xlpm.a_1 + _xlpm.a_2*(_xlpm.λ^2) + _xlpm.b_1*(_xlpm.λ^4) + _xlpm.a_3*(_xlpm.λ^-2) + _xlpm.a_4*(_xlpm.λ^-4) + _xlpm.a_5*(_xlpm.λ^-6) + _xlpm.a_6*(_xlpm.λ^-8)), IF(ISNUMBER(SEARCH("Sellmeier", _xlpm.EqName)), IF(ISNUMBER(SEARCH("Mod", _xlpm.EqName)), SQRT((2*_xlpm.Sellmeier(_xlpm.λX)+1)/(1-_xlpm.Sellmeier(_xlpm.λX))), SQRT(1+_xlpm.Sellmeier(_xlpm.λX)) ), IF(ISNUMBER(SEARCH("Schott", _xlpm.EqName)), SQRT(_xlpm.Schott(_xlpm.λX)), NA() ) ) )} -> 1.6061246 | M6: =K6-H6 -> 0.0087872766 | N6: =I6-H6 -> 0.0026649434 | O6: =L6-K6 -> 0.0047826812 | P6: =(I6-H6)/M6 -> 0.30327296 | Q6: =(L6-K6)/M6 -> 0.54427343 | R6: 0.0123 | S6: Sellmeier 3 | T6: 0.76124278 | U6: 0.74703337 | V6: 0.93892895 | W6: 0.0032117409 | X6: 0.014023442 | Y6: 139.52353 | Z6: 4.17 | AA6: 569 | AC6: Not Specified | AD6: Recommended
A7: 5 | B7: Ohara | C7: CaF | D7: S-FPM 3 | E7: =I7 -> 1.5377504 | F7: =(I7-1)/M7 -> 74.703998 | G7: {=_xlfn.LET( _xlpm.λe, Addendum!$A$47/1000, _xlpm.λF, Addendum!$A$63/1000, _xlpm.λC, Addendum!$A$38/1000, _xlpm.EqName, INDEX($S:$S, ROW()), _xlpm.a_1, INDEX($T:$T, ROW()), _xlpm.a_2, INDEX($U:$U, ROW()), _xlpm.a_3, INDEX($V:$V, ROW()), _xlpm.a_4, INDEX($W:$W, ROW()), _xlpm.a_5, INDEX($X:$X, ROW()), _xlpm.a_6, INDEX($Y:$Y, ROW()), _xlpm.b_1, IF(ISNUMBER(SEARCH("Schott 3/4", _xlpm.EqName)), IFERROR(_xlfn.TEXTAFTER(INDEX($AE:$AE, ROW()), "="), 0), 0), _xlpm.Sellmeier, _xlfn.LAMBDA(_xlpm.λ, _xlpm.a_1*_xlpm.λ^2/(_xlpm.λ^2-_xlpm.a_4) + _xlpm.a_2*_xlpm.λ^2/(_xlpm.λ^2-_xlpm.a_5) + _xlpm.a_3*_xlpm.λ^2/(_xlpm.λ^2-_xlpm.a_6)), _xlpm.Schott, _xlfn.LAMBDA(_xlpm.λ, _xlpm.a_1 + _xlpm.a_2*(_xlpm.λ^2) + _xlpm.b_1*(_xlpm.λ^4) + _xlpm.a_3*(_xlpm.λ^-2) + _xlpm.a_4*(_xlpm.λ^-4) + _xlpm.a_5*(_xlpm.λ^-6) + _xlpm.a_6*(_xlpm.λ^-8)), _xlpm.RefrIndex, _xlfn.LAMBDA(_xlpm.λ, IF(ISNUMBER(SEARCH("Sellmeier", _xlpm.EqName)), IF(ISNUMBER(SEARCH("Mod", _xlpm.EqName)), SQRT((2*_xlpm.Sellmeier(_xlpm.λ)+1)/(1-_xlpm.Sellmeier(_xlpm.λ))), SQRT(1+_xlpm.Sellmeier(_xlpm.λ)) ), IF(ISNUMBER(SEARCH("Schott", _xlpm.EqName)), SQRT(_xlpm.Schott(_xlpm.λ)), NA() ) ) ), _xlpm.ne, _xlpm.RefrIndex(_xlpm.λe), _xlpm.nF, _xlpm.RefrIndex(_xlpm.λF), _xlpm.nC, _xlpm.RefrIndex(_xlpm.λC), (_xlpm.ne - 1)/(_xlpm.nF - _xlpm.nC) )} -> 74.342047 | H7: {=_xlfn.LET( _xlpm.λX, _xlfn.SWITCH(INDEX($2:$2, COLUMN()), "nC", Addendum!$A$37/1000, "nd", Addendum!$A$46/1000, "ne", Addendum!$A$47/1000, "nF", Addendum!$A$62/1000, "ng", Addendum!$A$69/1000, ), _xlpm.EqName, INDEX($S:$S, ROW()), _xlpm.a_1, INDEX($T:$T, ROW()), _xlpm.a_2, INDEX($U:$U, ROW()), _xlpm.a_3, INDEX($V:$V, ROW()), _xlpm.a_4, INDEX($W:$W, ROW()), _xlpm.a_5, INDEX($X:$X, ROW()), _xlpm.a_6, INDEX($Y:$Y, ROW()), _xlpm.b_1, IF(ISNUMBER(SEARCH("Schott 3/4", _xlpm.EqName)), IFERROR(_xlfn.TEXTAFTER(INDEX($AE:$AE, ROW()), "="), 0), 0), _xlpm.Sellmeier, _xlfn.LAMBDA(_xlpm.λ, _xlpm.a_1*_xlpm.λ^2/(_xlpm.λ^2-_xlpm.a_4) + _xlpm.a_2*_xlpm.λ^2/(_xlpm.λ^2-_xlpm.a_5) + _xlpm.a_3*_xlpm.λ^2/(_xlpm.λ^2-_xlpm.a_6)), _xlpm.Schott, _xlfn.LAMBDA(_xlpm.λ, _xlpm.a_1 + _xlpm.a_2*(_xlpm.λ^2) + _xlpm.b_1*(_xlpm.λ^4) + _xlpm.a_3*(_xlpm.λ^-2) + _xlpm.a_4*(_xlpm.λ^-4) + _xlpm.a_5*(_xlpm.λ^-6) + _xlpm.a_6*(_xlpm.λ^-8)), IF(ISNUMBER(SEARCH("Sellmeier", _xlpm.EqName)), IF(ISNUMBER(SEARCH("Mod", _xlpm.EqName)), SQRT((2*_xlpm.Sellmeier(_xlpm.λX)+1)/(1-_xlpm.Sellmeier(_xlpm.λX))), SQRT(1+_xlpm.Sellmeier(_xlpm.λX)) ), IF(ISNUMBER(SEARCH("Schott", _xlpm.EqName)), SQRT(_xlpm.Schott(_xlpm.λX)), NA() ) ) )} -> 1.5355543 | I7: {=_xlfn.LET( _xlpm.λX, _xlfn.SWITCH(INDEX($2:$2, COLUMN()), "nC", Addendum!$A$37/1000, "nd", Addendum!$A$46/1000, "ne", Addendum!$A$47/1000, "nF", Addendum!$A$62/1000, "ng", Addendum!$A$69/1000, ), _xlpm.EqName, INDEX($S:$S, ROW()), _xlpm.a_1, INDEX($T:$T, ROW()), _xlpm.a_2, INDEX($U:$U, ROW()), _xlpm.a_3, INDEX($V:$V, ROW()), _xlpm.a_4, INDEX($W:$W, ROW()), _xlpm.a_5, INDEX($X:$X, ROW()), _xlpm.a_6, INDEX($Y:$Y, ROW()), _xlpm.b_1, IF(ISNUMBER(SEARCH("Schott 3/4", _xlpm.EqName)), IFERROR(_xlfn.TEXTAFTER(INDEX($AE:$AE, ROW()), "="), 0), 0), _xlpm.Sellmeier, _xlfn.LAMBDA(_xlpm.λ, _xlpm.a_1*_xlpm.λ^2/(_xlpm.λ^2-_xlpm.a_4) + _xlpm.a_2*_xlpm.λ^2/(_xlpm.λ^2-_xlpm.a_5) + _xlpm.a_3*_xlpm.λ^2/(_xlpm.λ^2-_xlpm.a_6)), _xlpm.Schott, _xlfn.LAMBDA(_xlpm.λ, _xlpm.a_1 + _xlpm.a_2*(_xlpm.λ^2) + _xlpm.b_1*(_xlpm.λ^4) + _xlpm.a_3*(_xlpm.λ^-2) + _xlpm.a_4*(_xlpm.λ^-4) + _xlpm.a_5*(_xlpm.λ^-6) + _xlpm.a_6*(_xlpm.λ^-8)), IF(ISNUMBER(SEARCH("Sellmeier", _xlpm.EqName)), IF(ISNUMBER(SEARCH("Mod", _xlpm.EqName)), SQRT((2*_xlpm.Sellmeier(_xlpm.λX)+1)/(1-_xlpm.Sellmeier(_xlpm.λX))), SQRT(1+_xlpm.Sellmeier(_xlpm.λX)) ), IF(ISNUMBER(SEARCH("Schott", _xlpm.EqName)), SQRT(_xlpm.Schott(_xlpm.λX)), NA() ) ) )} -> 1.5377504 | J7: {=_xlfn.LET( _xlpm.λX, _xlfn.SWITCH(INDEX($2:$2, COLUMN()), "nC", Addendum!$A$37/1000, "nd", Addendum!$A$46/1000, "ne", Addendum!$A$47/1000, "nF", Addendum!$A$62/1000, "ng", Addendum!$A$69/1000, ), _xlpm.EqName, INDEX($S:$S, ROW()), _xlpm.a_1, INDEX($T:$T, ROW()), _xlpm.a_2, INDEX($U:$U, ROW()), _xlpm.a_3, INDEX($V:$V, ROW()), _xlpm.a_4, INDEX($W:$W, ROW()), _xlpm.a_5, INDEX($X:$X, ROW()), _xlpm.a_6, INDEX($Y:$Y, ROW()), _xlpm.b_1, IF(ISNUMBER(SEARCH("Schott 3/4", _xlpm.EqName)), IFERROR(_xlfn.TEXTAFTER(INDEX($AE:$AE, ROW()), "="), 0), 0), _xlpm.Sellmeier, _xlfn.LAMBDA(_xlpm.λ, _xlpm.a_1*_xlpm.λ^2/(_xlpm.λ^2-_xlpm.a_4) + _xlpm.a_2*_xlpm.λ^2/(_xlpm.λ^2-_xlpm.a_5) + _xlpm.a_3*_xlpm.λ^2/(_xlpm.λ^2-_xlpm.a_6)), _xlpm.Schott, _xlfn.LAMBDA(_xlpm.λ, _xlpm.a_1 + _xlpm.a_2*(_xlpm.λ^2) + _xlpm.b_1*(_xlpm.λ^4) + _xlpm.a_3*(_xlpm.λ^-2) + _xlpm.a_4*(_xlpm.λ^-4) + _xlpm.a_5*(_xlpm.λ^-6) + _xlpm.a_6*(_xlpm.λ^-8)), IF(ISNUMBER(SEARCH("Sellmeier", _xlpm.EqName)), IF(ISNUMBER(SEARCH("Mod", _xlpm.EqName)), SQRT((2*_xlpm.Sellmeier(_xlpm.λX)+1)/(1-_xlpm.Sellmeier(_xlpm.λX))), SQRT(1+_xlpm.Sellmeier(_xlpm.λX)) ), IF(ISNUMBER(SEARCH("Schott", _xlpm.EqName)), SQRT(_xlpm.Schott(_xlpm.λX)), NA() ) ) )} -> 1.5394685 | K7: {=_xlfn.LET( _xlpm.λX, _xlfn.SWITCH(INDEX($2:$2, COLUMN()), "nC", Addendum!$A$37/1000, "nd", Addendum!$A$46/1000, "ne", Addendum!$A$47/1000, "nF", Addendum!$A$62/1000, "ng", Addendum!$A$69/1000, ), _xlpm.EqName, INDEX($S:$S, ROW()), _xlpm.a_1, INDEX($T:$T, ROW()), _xlpm.a_2, INDEX($U:$U, ROW()), _xlpm.a_3, INDEX($V:$V, ROW()), _xlpm.a_4, INDEX($W:$W, ROW()), _xlpm.a_5, INDEX($X:$X, ROW()), _xlpm.a_6, INDEX($Y:$Y, ROW()), _xlpm.b_1, IF(ISNUMBER(SEARCH("Schott 3/4", _xlpm.EqName)), IFERROR(_xlfn.TEXTAFTER(INDEX($AE:$AE, ROW()), "="), 0), 0), _xlpm.Sellmeier, _xlfn.LAMBDA(_xlpm.λ, _xlpm.a_1*_xlpm.λ^2/(_xlpm.λ^2-_xlpm.a_4) + _xlpm.a_2*_xlpm.λ^2/(_xlpm.λ^2-_xlpm.a_5) + _xlpm.a_3*_xlpm.λ^2/(_xlpm.λ^2-_xlpm.a_6)), _xlpm.Schott, _xlfn.LAMBDA(_xlpm.λ, _xlpm.a_1 + _xlpm.a_2*(_xlpm.λ^2) + _xlpm.b_1*(_xlpm.λ^4) + _xlpm.a_3*(_xlpm.λ^-2) + _xlpm.a_4*(_xlpm.λ^-4) + _xlpm.a_5*(_xlpm.λ^-6) + _xlpm.a_6*(_xlpm.λ^-8)), IF(ISNUMBER(SEARCH("Sellmeier", _xlpm.EqName)), IF(ISNUMBER(SEARCH("Mod", _xlpm.EqName)), SQRT((2*_xlpm.Sellmeier(_xlpm.λX)+1)/(1-_xlpm.Sellmeier(_xlpm.λX))), SQRT(1+_xlpm.Sellmeier(_xlpm.λX)) ), IF(ISNUMBER(SEARCH("Schott", _xlpm.EqName)), SQRT(_xlpm.Schott(_xlpm.λX)), NA() ) ) )} -> 1.5427527 | L7: {=_xlfn.LET( _xlpm.λX, _xlfn.SWITCH(INDEX($2:$2, COLUMN()), "nC", Addendum!$A$37/1000, "nd", Addendum!$A$46/1000, "ne", Addendum!$A$47/1000, "nF", Addendum!$A$62/1000, "ng", Addendum!$A$69/1000, ), _xlpm.EqName, INDEX($S:$S, ROW()), _xlpm.a_1, INDEX($T:$T, ROW()), _xlpm.a_2, INDEX($U:$U, ROW()), _xlpm.a_3, INDEX($V:$V, ROW()), _xlpm.a_4, INDEX($W:$W, ROW()), _xlpm.a_5, INDEX($X:$X, ROW()), _xlpm.a_6, INDEX($Y:$Y, ROW()), _xlpm.b_1, IF(ISNUMBER(SEARCH("Schott 3/4", _xlpm.EqName)), IFERROR(_xlfn.TEXTAFTER(INDEX($AE:$AE, ROW()), "="), 0), 0), _xlpm.Sellmeier, _xlfn.LAMBDA(_xlpm.λ, _xlpm.a_1*_xlpm.λ^2/(_xlpm.λ^2-_xlpm.a_4) + _xlpm.a_2*_xlpm.λ^2/(_xlpm.λ^2-_xlpm.a_5) + _xlpm.a_3*_xlpm.λ^2/(_xlpm.λ^2-_xlpm.a_6)), _xlpm.Schott, _xlfn.LAMBDA(_xlpm.λ, _xlpm.a_1 + _xlpm.a_2*(_xlpm.λ^2) + _xlpm.b_1*(_xlpm.λ^4) + _xlpm.a_3*(_xlpm.λ^-2) + _xlpm.a_4*(_xlpm.λ^-4) + _xlpm.a_5*(_xlpm.λ^-6) + _xlpm.a_6*(_xlpm.λ^-8)), IF(ISNUMBER(SEARCH("Sellmeier", _xlpm.EqName)), IF(ISNUMBER(SEARCH("Mod", _xlpm.EqName)), SQRT((2*_xlpm.Sellmeier(_xlpm.λX)+1)/(1-_xlpm.Sellmeier(_xlpm.λX))), SQRT(1+_xlpm.Sellmeier(_xlpm.λX)) ), IF(ISNUMBER(SEARCH("Schott", _xlpm.EqName)), SQRT(_xlpm.Schott(_xlpm.λX)), NA() ) ) )} -> 1.5466354 | M7: =K7-H7 -> 0.0071984147 | N7: =I7-H7 -> 0.0021960562 | O7: =L7-K7 -> 0.0038826389 | P7: =(I7-H7)/M7 -> 0.30507498 | Q7: =(L7-K7)/M7 -> 0.53937416 | R7: 0.0186 | S7: Sellmeier 3 | T7: 0.80940729 | U7: 0.52700703 | V7: 0.9091277 | W7: 0.0037607239 | X7: 0.013565489 | Y7: 142.50361 | Z7: 3.64 | AA7: 505 | AC7: Not Specified | AD7: Recommended
A8: 6 | B8: Ohara | C8: CaF | D8: S-FPM 4 | E8: =I8 -> 1.5284102 | F8: =(I8-1)/M8 -> 76.453724 | G8: {=_xlfn.LET( _xlpm.λe, Addendum!$A$47/1000, _xlpm.λF, Addendum!$A$63/1000, _xlpm.λC, Addendum!$A$38/1000, _xlpm.EqName, INDEX($S:$S, ROW()), _xlpm.a_1, INDEX($T:$T, ROW()), _xlpm.a_2, INDEX($U:$U, ROW()), _xlpm.a_3, INDEX($V:$V, ROW()), _xlpm.a_4, INDEX($W:$W, ROW()), _xlpm.a_5, INDEX($X:$X, ROW()), _xlpm.a_6, INDEX($Y:$Y, ROW()), _xlpm.b_1, IF(ISNUMBER(SEARCH("Schott 3/4", _xlpm.EqName)), IFERROR(_xlfn.TEXTAFTER(INDEX($AE:$AE, ROW()), "="), 0), 0), _xlpm.Sellmeier, _xlfn.LAMBDA(_xlpm.λ, _xlpm.a_1*_xlpm.λ^2/(_xlpm.λ^2-_xlpm.a_4) + _xlpm.a_2*_xlpm.λ^2/(_xlpm.λ^2-_xlpm.a_5) + _xlpm.a_3*_xlpm.λ^2/(_xlpm.λ^2-_xlpm.a_6)), _xlpm.Schott, _xlfn.LAMBDA(_xlpm.λ, _xlpm.a_1 + _xlpm.a_2*(_xlpm.λ^2) + _xlpm.b_1*(_xlpm.λ^4) + _xlpm.a_3*(_xlpm.λ^-2) + _xlpm.a_4*(_xlpm.λ^-4) + _xlpm.a_5*(_xlpm.λ^-6) + _xlpm.a_6*(_xlpm.λ^-8)), _xlpm.RefrIndex, _xlfn.LAMBDA(_xlpm.λ, IF(ISNUMBER(SEARCH("Sellmeier", _xlpm.EqName)), IF(ISNUMBER(SEARCH("Mod", _xlpm.EqName)), SQRT((2*_xlpm.Sellmeier(_xlpm.λ)+1)/(1-_xlpm.Sellmeier(_xlpm.λ))), SQRT(1+_xlpm.Sellmeier(_xlpm.λ)) ), IF(ISNUMBER(SEARCH("Schott", _xlpm.EqName)), SQRT(_xlpm.Schott(_xlpm.λ)), NA() ) ) ), _xlpm.ne, _xlpm.RefrIndex(_xlpm.λe), _xlpm.nF, _xlpm.RefrIndex(_xlpm.λF), _xlpm.nC, _xlpm.RefrIndex(_xlpm.λC), (_xlpm.ne - 1)/(_xlpm.nF - _xlpm.nC) )} -> 76.073455 | H8: {=_xlfn.LET( _xlpm.λX, _xlfn.SWITCH(INDEX($2:$2, COLUMN()), "nC", Addendum!$A$37/1000, "nd", Addendum!$A$46/1000, "ne", Addendum!$A$47/1000, "nF", Addendum!$A$62/1000, "ng", Addendum!$A$69/1000, ), _xlpm.EqName, INDEX($S:$S, ROW()), _xlpm.a_1, INDEX($T:$T, ROW()), _xlpm.a_2, INDEX($U:$U, ROW()), _xlpm.a_3, INDEX($V:$V, ROW()), _xlpm.a_4, INDEX($W:$W, ROW()), _xlpm.a_5, INDEX($X:$X, ROW()), _xlpm.a_6, INDEX($Y:$Y, ROW()), _xlpm.b_1, IF(ISNUMBER(SEARCH("Schott 3/4", _xlpm.EqName)), IFERROR(_xlfn.TEXTAFTER(INDEX($AE:$AE, ROW()), "="), 0), 0), _xlpm.Sellmeier, _xlfn.LAMBDA(_xlpm.λ, _xlpm.a_1*_xlpm.λ^2/(_xlpm.λ^2-_xlpm.a_4) + _xlpm.a_2*_xlpm.λ^2/(_xlpm.λ^2-_xlpm.a_5) + _xlpm.a_3*_xlpm.λ^2/(_xlpm.λ^2-_xlpm.a_6)), _xlpm.Schott, _xlfn.LAMBDA(_xlpm.λ, _xlpm.a_1 + _xlpm.a_2*(_xlpm.λ^2) + _xlpm.b_1*(_xlpm.λ^4) + _xlpm.a_3*(_xlpm.λ^-2) + _xlpm.a_4*(_xlpm.λ^-4) + _xlpm.a_5*(_xlpm.λ^-6) + _xlpm.a_6*(_xlpm.λ^-8)), IF(ISNUMBER(SEARCH("Sellmeier", _xlpm.EqName)), IF(ISNUMBER(SEARCH("Mod", _xlpm.EqName)), SQRT((2*_xlpm.Sellmeier(_xlpm.λX)+1)/(1-_xlpm.Sellmeier(_xlpm.λX))), SQRT(1+_xlpm.Sellmeier(_xlpm.λX)) ), IF(ISNUMBER(SEARCH("Schott", _xlpm.EqName)), SQRT(_xlpm.Schott(_xlpm.λX)), NA() ) ) )} -> 1.5263026 | I8: {=_xlfn.LET( _xlpm.λX, _xlfn.SWITCH(INDEX($2:$2, COLUMN()), "nC", Addendum!$A$37/1000, "nd", Addendum!$A$46/1000, "ne", Addendum!$A$47/1000, "nF", Addendum!$A$62/1000, "ng", Addendum!$A$69/1000, ), _xlpm.EqName, INDEX($S:$S, ROW()), _xlpm.a_1, INDEX($T:$T, ROW()), _xlpm.a_2, INDEX($U:$U, ROW()), _xlpm.a_3, INDEX($V:$V, ROW()), _xlpm.a_4, INDEX($W:$W, ROW()), _xlpm.a_5, INDEX($X:$X, ROW()), _xlpm.a_6, INDEX($Y:$Y, ROW()), _xlpm.b_1, IF(ISNUMBER(SEARCH("Schott 3/4", _xlpm.EqName)), IFERROR(_xlfn.TEXTAFTER(INDEX($AE:$AE, ROW()), "="), 0), 0), _xlpm.Sellmeier, _xlfn.LAMBDA(_xlpm.λ, _xlpm.a_1*_xlpm.λ^2/(_xlpm.λ^2-_xlpm.a_4) + _xlpm.a_2*_xlpm.λ^2/(_xlpm.λ^2-_xlpm.a_5) + _xlpm.a_3*_xlpm.λ^2/(_xlpm.λ^2-_xlpm.a_6)), _xlpm.Schott, _xlfn.LAMBDA(_xlpm.λ, _xlpm.a_1 + _xlpm.a_2*(_xlpm.λ^2) + _xlpm.b_1*(_xlpm.λ^4) + _xlpm.a_3*(_xlpm.λ^-2) + _xlpm.a_4*(_xlpm.λ^-4) + _xlpm.a_5*(_xlpm.λ^-6) + _xlpm.a_6*(_xlpm.λ^-8)), IF(ISNUMBER(SEARCH("Sellmeier", _xlpm.EqName)), IF(ISNUMBER(SEARCH("Mod", _xlpm.EqName)), SQRT((2*_xlpm.Sellmeier(_xlpm.λX)+1)/(1-_xlpm.Sellmeier(_xlpm.λX))), SQRT(1+_xlpm.Sellmeier(_xlpm.λX)) ), IF(ISNUMBER(SEARCH("Schott", _xlpm.EqName)), SQRT(_xlpm.Schott(_xlpm.λX)), NA() ) ) )} -> 1.5284102 | J8: {=_xlfn.LET( _xlpm.λX, _xlfn.SWITCH(INDEX($2:$2, COLUMN()), "nC", Addendum!$A$37/1000, "nd", Addendum!$A$46/1000, "ne", Addendum!$A$47/1000, "nF", Addendum!$A$62/1000, "ng", Addendum!$A$69/1000, ), _xlpm.EqName, INDEX($S:$S, ROW()), _xlpm.a_1, INDEX($T:$T, ROW()), _xlpm.a_2, INDEX($U:$U, ROW()), _xlpm.a_3, INDEX($V:$V, ROW()), _xlpm.a_4, INDEX($W:$W, ROW()), _xlpm.a_5, INDEX($X:$X, ROW()), _xlpm.a_6, INDEX($Y:$Y, ROW()), _xlpm.b_1, IF(ISNUMBER(SEARCH("Schott 3/4", _xlpm.EqName)), IFERROR(_xlfn.TEXTAFTER(INDEX($AE:$AE, ROW()), "="), 0), 0), _xlpm.Sellmeier, _xlfn.LAMBDA(_xlpm.λ, _xlpm.a_1*_xlpm.λ^2/(_xlpm.λ^2-_xlpm.a_4) + _xlpm.a_2*_xlpm.λ^2/(_xlpm.λ^2-_xlpm.a_5) + _xlpm.a_3*_xlpm.λ^2/(_xlpm.λ^2-_xlpm.a_6)), _xlpm.Schott, _xlfn.LAMBDA(_xlpm.λ, _xlpm.a_1 + _xlpm.a_2*(_xlpm.λ^2) + _xlpm.b_1*(_xlpm.λ^4) + _xlpm.a_3*(_xlpm.λ^-2) + _xlpm.a_4*(_xlpm.λ^-4) + _xlpm.a_5*(_xlpm.λ^-6) + _xlpm.a_6*(_xlpm.λ^-8)), IF(ISNUMBER(SEARCH("Sellmeier", _xlpm.EqName)), IF(ISNUMBER(SEARCH("Mod", _xlpm.EqName)), SQRT((2*_xlpm.Sellmeier(_xlpm.λX)+1)/(1-_xlpm.Sellmeier(_xlpm.λX))), SQRT(1+_xlpm.Sellmeier(_xlpm.λX)) ), IF(ISNUMBER(SEARCH("Schott", _xlpm.EqName)), SQRT(_xlpm.Schott(_xlpm.λX)), NA() ) ) )} -> 1.53006 | K8: {=_xlfn.LET( _xlpm.λX, _xlfn.SWITCH(INDEX($2:$2, COLUMN()), "nC", Addendum!$A$37/1000, "nd", Addendum!$A$46/1000, "ne", Addendum!$A$47/1000, "nF", Addendum!$A$62/1000, "ng", Addendum!$A$69/1000, ), _xlpm.EqName, INDEX($S:$S, ROW()), _xlpm.a_1, INDEX($T:$T, ROW()), _xlpm.a_2, INDEX($U:$U, ROW()), _xlpm.a_3, INDEX($V:$V, ROW()), _xlpm.a_4, INDEX($W:$W, ROW()), _xlpm.a_5, INDEX($X:$X, ROW()), _xlpm.a_6, INDEX($Y:$Y, ROW()), _xlpm.b_1, IF(ISNUMBER(SEARCH("Schott 3/4", _xlpm.EqName)), IFERROR(_xlfn.TEXTAFTER(INDEX($AE:$AE, ROW()), "="), 0), 0), _xlpm.Sellmeier, _xlfn.LAMBDA(_xlpm.λ, _xlpm.a_1*_xlpm.λ^2/(_xlpm.λ^2-_xlpm.a_4) + _xlpm.a_2*_xlpm.λ^2/(_xlpm.λ^2-_xlpm.a_5) + _xlpm.a_3*_xlpm.λ^2/(_xlpm.λ^2-_xlpm.a_6)), _xlpm.Schott, _xlfn.LAMBDA(_xlpm.λ, _xlpm.a_1 + _xlpm.a_2*(_xlpm.λ^2) + _xlpm.b_1*(_xlpm.λ^4) + _xlpm.a_3*(_xlpm.λ^-2) + _xlpm.a_4*(_xlpm.λ^-4) + _xlpm.a_5*(_xlpm.λ^-6) + _xlpm.a_6*(_xlpm.λ^-8)), IF(ISNUMBER(SEARCH("Sellmeier", _xlpm.EqName)), IF(ISNUMBER(SEARCH("Mod", _xlpm.EqName)), SQRT((2*_xlpm.Sellmeier(_xlpm.λX)+1)/(1-_xlpm.Sellmeier(_xlpm.λX))), SQRT(1+_xlpm.Sellmeier(_xlpm.λX)) ), IF(ISNUMBER(SEARCH("Schott", _xlpm.EqName)), SQRT(_xlpm.Schott(_xlpm.λX)), NA() ) ) )} -> 1.5332141 | L8: {=_xlfn.LET( _xlpm.λX, _xlfn.SWITCH(INDEX($2:$2, COLUMN()), "nC", Addendum!$A$37/1000, "nd", Addendum!$A$46/1000, "ne", Addendum!$A$47/1000, "nF", Addendum!$A$62/1000, "ng", Addendum!$A$69/1000, ), _xlpm.EqName, INDEX($S:$S, ROW()), _xlpm.a_1, INDEX($T:$T, ROW()), _xlpm.a_2, INDEX($U:$U, ROW()), _xlpm.a_3, INDEX($V:$V, ROW()), _xlpm.a_4, INDEX($W:$W, ROW()), _xlpm.a_5, INDEX($X:$X, ROW()), _xlpm.a_6, INDEX($Y:$Y, ROW()), _xlpm.b_1, IF(ISNUMBER(SEARCH("Schott 3/4", _xlpm.EqName)), IFERROR(_xlfn.TEXTAFTER(INDEX($AE:$AE, ROW()), "="), 0), 0), _xlpm.Sellmeier, _xlfn.LAMBDA(_xlpm.λ, _xlpm.a_1*_xlpm.λ^2/(_xlpm.λ^2-_xlpm.a_4) + _xlpm.a_2*_xlpm.λ^2/(_xlpm.λ^2-_xlpm.a_5) + _xlpm.a_3*_xlpm.λ^2/(_xlpm.λ^2-_xlpm.a_6)), _xlpm.Schott, _xlfn.LAMBDA(_xlpm.λ, _xlpm.a_1 + _xlpm.a_2*(_xlpm.λ^2) + _xlpm.b_1*(_xlpm.λ^4) + _xlpm.a_3*(_xlpm.λ^-2) + _xlpm.a_4*(_xlpm.λ^-4) + _xlpm.a_5*(_xlpm.λ^-6) + _xlpm.a_6*(_xlpm.λ^-8)), IF(ISNUMBER(SEARCH("Sellmeier", _xlpm.EqName)), IF(ISNUMBER(SEARCH("Mod", _xlpm.EqName)), SQRT((2*_xlpm.Sellmeier(_xlpm.λX)+1)/(1-_xlpm.Sellmeier(_xlpm.λX))), SQRT(1+_xlpm.Sellmeier(_xlpm.λX)) ), IF(ISNUMBER(SEARCH("Schott", _xlpm.EqName)), SQRT(_xlpm.Schott(_xlpm.λX)), NA() ) ) )} -> 1.5369433 | M8: =K8-H8 -> 0.0069115043 | N8: =I8-H8 -> 0.0021075953 | O8: =L8-K8 -> 0.0037291062 | P8: =(I8-H8)/M8 -> 0.30494017 | Q8: =(L8-K8)/M8 -> 0.53955059 | R8: 0.0218 | S8: Sellmeier 3 | T8: 0.68558508 | U8: 0.62338021 | V8: 0.91417839 | W8: 0.0028817201 | X8: 0.012470171 | Y8: 153.5772 | Z8: 3.76 | AA8: 487 | AC8: Not Specified | AD8: Recommended
A9: 7 | B9: Ohara | C9: CaF | D9: S-FPM 5 | E9: =I9 -> 1.5520002 | F9: =(I9-1)/M9 -> 70.697902 | G9: {=_xlfn.LET( _xlpm.λe, Addendum!$A$47/1000, _xlpm.λF, Addendum!$A$63/1000, _xlpm.λC, Addendum!$A$38/1000, _xlpm.EqName, INDEX($S:$S, ROW()), _xlpm.a_1, INDEX($T:$T, ROW()), _xlpm.a_2, INDEX($U:$U, ROW()), _xlpm.a_3, INDEX($V:$V, ROW()), _xlpm.a_4, INDEX($W:$W, ROW()), _xlpm.a_5, INDEX($X:$X, ROW()), _xlpm.a_6, INDEX($Y:$Y, ROW()), _xlpm.b_1, IF(ISNUMBER(SEARCH("Schott 3/4", _xlpm.EqName)), IFERROR(_xlfn.TEXTAFTER(INDEX($AE:$AE, ROW()), "="), 0), 0), _xlpm.Sellmeier, _xlfn.LAMBDA(_xlpm.λ, _xlpm.a_1*_xlpm.λ^2/(_xlpm.λ^2-_xlpm.a_4) + _xlpm.a_2*_xlpm.λ^2/(_xlpm.λ^2-_xlpm.a_5) + _xlpm.a_3*_xlpm.λ^2/(_xlpm.λ^2-_xlpm.a_6)), _xlpm.Schott, _xlfn.LAMBDA(_xlpm.λ, _xlpm.a_1 + _xlpm.a_2*(_xlpm.λ^2) + _xlpm.b_1*(_xlpm.λ^4) + _xlpm.a_3*(_xlpm.λ^-2) + _xlpm.a_4*(_xlpm.λ^-4) + _xlpm.a_5*(_xlpm.λ^-6) + _xlpm.a_6*(_xlpm.λ^-8)), _xlpm.RefrIndex, _xlfn.LAMBDA(_xlpm.λ, IF(ISNUMBER(SEARCH("Sellmeier", _xlpm.EqName)), IF(ISNUMBER(SEARCH("Mod", _xlpm.EqName)), SQRT((2*_xlpm.Sellmeier(_xlpm.λ)+1)/(1-_xlpm.Sellmeier(_xlpm.λ))), SQRT(1+_xlpm.Sellmeier(_xlpm.λ)) ), IF(ISNUMBER(SEARCH("Schott", _xlpm.EqName)), SQRT(_xlpm.Schott(_xlpm.λ)), NA() ) ) ), _xlpm.ne, _xlpm.RefrIndex(_xlpm.λe), _xlpm.nF, _xlpm.RefrIndex(_xlpm.λF), _xlpm.nC, _xlpm.RefrIndex(_xlpm.λC), (_xlpm.ne - 1)/(_xlpm.nF - _xlpm.nC) )} -> 70.3377 | H9: {=_xlfn.LET( _xlpm.λX, _xlfn.SWITCH(INDEX($2:$2, COLUMN()), "nC", Addendum!$A$37/1000, "nd", Addendum!$A$46/1000, "ne", Addendum!$A$47/1000, "nF", Addendum!$A$62/1000, "ng", Addendum!$A$69/1000, ), _xlpm.EqName, INDEX($S:$S, ROW()), _xlpm.a_1, INDEX($T:$T, ROW()), _xlpm.a_2, INDEX($U:$U, ROW()), _xlpm.a_3, INDEX($V:$V, ROW()), _xlpm.a_4, INDEX($W:$W, ROW()), _xlpm.a_5, INDEX($X:$X, ROW()), _xlpm.a_6, INDEX($Y:$Y, ROW()), _xlpm.b_1, IF(ISNUMBER(SEARCH("Schott 3/4", _xlpm.EqName)), IFERROR(_xlfn.TEXTAFTER(INDEX($AE:$AE, ROW()), "="), 0), 0), _xlpm.Sellmeier, _xlfn.LAMBDA(_xlpm.λ, _xlpm.a_1*_xlpm.λ^2/(_xlpm.λ^2-_xlpm.a_4) + _xlpm.a_2*_xlpm.λ^2/(_xlpm.λ^2-_xlpm.a_5) + _xlpm.a_3*_xlpm.λ^2/(_xlpm.λ^2-_xlpm.a_6)), _xlpm.Schott, _xlfn.LAMBDA(_xlpm.λ, _xlpm.a_1 + _xlpm.a_2*(_xlpm.λ^2) + _xlpm.b_1*(_xlpm.λ^4) + _xlpm.a_3*(_xlpm.λ^-2) + _xlpm.a_4*(_xlpm.λ^-4) + _xlpm.a_5*(_xlpm.λ^-6) + _xlpm.a_6*(_xlpm.λ^-8)), IF(ISNUMBER(SEARCH("Sellmeier", _xlpm.EqName)), IF(ISNUMBER(SEARCH("Mod", _xlpm.EqName)), SQRT((2*_xlpm.Sellmeier(_xlpm.λX)+1)/(1-_xlpm.Sellmeier(_xlpm.λX))), SQRT(1+_xlpm.Sellmeier(_xlpm.λX)) ), IF(ISNUMBER(SEARCH("Schott", _xlpm.EqName)), SQRT(_xlpm.Schott(_xlpm.λX)), NA() ) ) )} -> 1.5496253 | I9: {=_xlfn.LET( _xlpm.λX, _xlfn.SWITCH(INDEX($2:$2, COLUMN()), "nC", Addendum!$A$37/1000, "nd", Addendum!$A$46/1000, "ne", Addendum!$A$47/1000, "nF", Addendum!$A$62/1000, "ng", Addendum!$A$69/1000, ), _xlpm.EqName, INDEX($S:$S, ROW()), _xlpm.a_1, INDEX($T:$T, ROW()), _xlpm.a_2, INDEX($U:$U, ROW()), _xlpm.a_3, INDEX($V:$V, ROW()), _xlpm.a_4, INDEX($W:$W, ROW()), _xlpm.a_5, INDEX($X:$X, ROW()), _xlpm.a_6, INDEX($Y:$Y, ROW()), _xlpm.b_1, IF(ISNUMBER(SEARCH("Schott 3/4", _xlpm.EqName)), IFERROR(_xlfn.TEXTAFTER(INDEX($AE:$AE, ROW()), "="), 0), 0), _xlpm.Sellmeier, _xlfn.LAMBDA(_xlpm.λ, _xlpm.a_1*_xlpm.λ^2/(_xlpm.λ^2-_xlpm.a_4) + _xlpm.a_2*_xlpm.λ^2/(_xlpm.λ^2-_xlpm.a_5) + _xlpm.a_3*_xlpm.λ^2/(_xlpm.λ^2-_xlpm.a_6)), _xlpm.Schott, _xlfn.LAMBDA(_xlpm.λ, _xlpm.a_1 + _xlpm.a_2*(_xlpm.λ^2) + _xlpm.b_1*(_xlpm.λ^4) + _xlpm.a_3*(_xlpm.λ^-2) + _xlpm.a_4*(_xlpm.λ^-4) + _xlpm.a_5*(_xlpm.λ^-6) + _xlpm.a_6*(_xlpm.λ^-8)), IF(ISNUMBER(SEARCH("Sellmeier", _xlpm.EqName)), IF(ISNUMBER(SEARCH("Mod", _xlpm.EqName)), SQRT((2*_xlpm.Sellmeier(_xlpm.λX)+1)/(1-_xlpm.Sellmeier(_xlpm.λX))), SQRT(1+_xlpm.Sellmeier(_xlpm.λX)) ), IF(ISNUMBER(SEARCH("Schott", _xlpm.EqName)), SQRT(_xlpm.Schott(_xlpm.λX)), NA() ) ) )} -> 1.5520002 | J9: {=_xlfn.LET( _xlpm.λX, _xlfn.SWITCH(INDEX($2:$2, COLUMN()), "nC", Addendum!$A$37/1000, "nd", Addendum!$A$46/1000, "ne", Addendum!$A$47/1000, "nF", Addendum!$A$62/1000, "ng", Addendum!$A$69/1000, ), _xlpm.EqName, INDEX($S:$S, ROW()), _xlpm.a_1, INDEX($T:$T, ROW()), _xlpm.a_2, INDEX($U:$U, ROW()), _xlpm.a_3, INDEX($V:$V, ROW()), _xlpm.a_4, INDEX($W:$W, ROW()), _xlpm.a_5, INDEX($X:$X, ROW()), _xlpm.a_6, INDEX($Y:$Y, ROW()), _xlpm.b_1, IF(ISNUMBER(SEARCH("Schott 3/4", _xlpm.EqName)), IFERROR(_xlfn.TEXTAFTER(INDEX($AE:$AE, ROW()), "="), 0), 0), _xlpm.Sellmeier, _xlfn.LAMBDA(_xlpm.λ, _xlpm.a_1*_xlpm.λ^2/(_xlpm.λ^2-_xlpm.a_4) + _xlpm.a_2*_xlpm.λ^2/(_xlpm.λ^2-_xlpm.a_5) + _xlpm.a_3*_xlpm.λ^2/(_xlpm.λ^2-_xlpm.a_6)), _xlpm.Schott, _xlfn.LAMBDA(_xlpm.λ, _xlpm.a_1 + _xlpm.a_2*(_xlpm.λ^2) + _xlpm.b_1*(_xlpm.λ^4) + _xlpm.a_3*(_xlpm.λ^-2) + _xlpm.a_4*(_xlpm.λ^-4) + _xlpm.a_5*(_xlpm.λ^-6) + _xlpm.a_6*(_xlpm.λ^-8)), IF(ISNUMBER(SEARCH("Sellmeier", _xlpm.EqName)), IF(ISNUMBER(SEARCH("Mod", _xlpm.EqName)), SQRT((2*_xlpm.Sellmeier(_xlpm.λX)+1)/(1-_xlpm.Sellmeier(_xlpm.λX))), SQRT(1+_xlpm.Sellmeier(_xlpm.λX)) ), IF(ISNUMBER(SEARCH("Schott", _xlpm.EqName)), SQRT(_xlpm.Schott(_xlpm.λX)), NA() ) ) )} -> 1.5538632 | K9: {=_xlfn.LET( _xlpm.λX, _xlfn.SWITCH(INDEX($2:$2, COLUMN()), "nC", Addendum!$A$37/1000, "nd", Addendum!$A$46/1000, "ne", Addendum!$A$47/1000, "nF", Addendum!$A$62/1000, "ng", Addendum!$A$69/1000, ), _xlpm.EqName, INDEX($S:$S, ROW()), _xlpm.a_1, INDEX($T:$T, ROW()), _xlpm.a_2, INDEX($U:$U, ROW()), _xlpm.a_3, INDEX($V:$V, ROW()), _xlpm.a_4, INDEX($W:$W, ROW()), _xlpm.a_5, INDEX($X:$X, ROW()), _xlpm.a_6, INDEX($Y:$Y, ROW()), _xlpm.b_1, IF(ISNUMBER(SEARCH("Schott 3/4", _xlpm.EqName)), IFERROR(_xlfn.TEXTAFTER(INDEX($AE:$AE, ROW()), "="), 0), 0), _xlpm.Sellmeier, _xlfn.LAMBDA(_xlpm.λ, _xlpm.a_1*_xlpm.λ^2/(_xlpm.λ^2-_xlpm.a_4) + _xlpm.a_2*_xlpm.λ^2/(_xlpm.λ^2-_xlpm.a_5) + _xlpm.a_3*_xlpm.λ^2/(_xlpm.λ^2-_xlpm.a_6)), _xlpm.Schott, _xlfn.LAMBDA(_xlpm.λ, _xlpm.a_1 + _xlpm.a_2*(_xlpm.λ^2) + _xlpm.b_1*(_xlpm.λ^4) + _xlpm.a_3*(_xlpm.λ^-2) + _xlpm.a_4*(_xlpm.λ^-4) + _xlpm.a_5*(_xlpm.λ^-6) + _xlpm.a_6*(_xlpm.λ^-8)), IF(ISNUMBER(SEARCH("Sellmeier", _xlpm.EqName)), IF(ISNUMBER(SEARCH("Mod", _xlpm.EqName)), SQRT((2*_xlpm.Sellmeier(_xlpm.λX)+1)/(1-_xlpm.Sellmeier(_xlpm.λX))), SQRT(1+_xlpm.Sellmeier(_xlpm.λX)) ), IF(ISNUMBER(SEARCH("Schott", _xlpm.EqName)), SQRT(_xlpm.Schott(_xlpm.λX)), NA() ) ) )} -> 1.5574332 | L9: {=_xlfn.LET( _xlpm.λX, _xlfn.SWITCH(INDEX($2:$2, COLUMN()), "nC", Addendum!$A$37/1000, "nd", Addendum!$A$46/1000, "ne", Addendum!$A$47/1000, "nF", Addendum!$A$62/1000, "ng", Addendum!$A$69/1000, ), _xlpm.EqName, INDEX($S:$S, ROW()), _xlpm.a_1, INDEX($T:$T, ROW()), _xlpm.a_2, INDEX($U:$U, ROW()), _xlpm.a_3, INDEX($V:$V, ROW()), _xlpm.a_4, INDEX($W:$W, ROW()), _xlpm.a_5, INDEX($X:$X, ROW()), _xlpm.a_6, INDEX($Y:$Y, ROW()), _xlpm.b_1, IF(ISNUMBER(SEARCH("Schott 3/4", _xlpm.EqName)), IFERROR(_xlfn.TEXTAFTER(INDEX($AE:$AE, ROW()), "="), 0), 0), _xlpm.Sellmeier, _xlfn.LAMBDA(_xlpm.λ, _xlpm.a_1*_xlpm.λ^2/(_xlpm.λ^2-_xlpm.a_4) + _xlpm.a_2*_xlpm.λ^2/(_xlpm.λ^2-_xlpm.a_5) + _xlpm.a_3*_xlpm.λ^2/(_xlpm.λ^2-_xlpm.a_6)), _xlpm.Schott, _xlfn.LAMBDA(_xlpm.λ, _xlpm.a_1 + _xlpm.a_2*(_xlpm.λ^2) + _xlpm.b_1*(_xlpm.λ^4) + _xlpm.a_3*(_xlpm.λ^-2) + _xlpm.a_4*(_xlpm.λ^-4) + _xlpm.a_5*(_xlpm.λ^-6) + _xlpm.a_6*(_xlpm.λ^-8)), IF(ISNUMBER(SEARCH("Sellmeier", _xlpm.EqName)), IF(ISNUMBER(SEARCH("Mod", _xlpm.EqName)), SQRT((2*_xlpm.Sellmeier(_xlpm.λX)+1)/(1-_xlpm.Sellmeier(_xlpm.λX))), SQRT(1+_xlpm.Sellmeier(_xlpm.λX)) ), IF(ISNUMBER(SEARCH("Schott", _xlpm.EqName)), SQRT(_xlpm.Schott(_xlpm.λX)), NA() ) ) )} -> 1.5616667 | M9: =K9-H9 -> 0.0078078727 | N9: =I9-H9 -> 0.0023748805 | O9: =L9-K9 -> 0.0042334533 | P9: =(I9-H9)/M9 -> 0.30416486 | Q9: =(L9-K9)/M9 -> 0.54220317 | R9: 0.015 | S9: Sellmeier 3 | T9: 0.83989976 | U9: 0.53772131 | V9: 0.95324776 | W9: 0.003764483 | X9: 0.014802262 | Y9: 145.67555 | Z9: 3.74 | AA9: 474 | AC9: Not Specified | AD9: Recommended
